Workbook

Sheet Guide
A1: Scalyo — simulateur de seuil de rentabilité, modèle coréen (version française)
A2: Traduction du classeur coréen du 24/09/2026 · montants en wons (KRW) · tarifs issus du code (functions/api/_config/prices.js)
A4: Ce que vous obtenez
A5: ① « Calculateur » : saisissez le nombre moyen de clients et de sièges par client ; vous obtenez le bénéfice net mensuel, le renfort de support nécessaire, le résultat par client Enterprise et le seuil de rentabilité.
A6: ② « Synthese » : selon les hypothèses, le mois du premier bénéfice net, le seuil cumulé, l'épuisement de la trésorerie et le premier recrutement de support, avec un repère en euros.
A7: ③ « Previsions » / « Annuel » : compte de résultat mensuel sur 60 mois et synthèse sur 5 exercices (IS coréen, report des déficits).
A9: Définition du bénéfice net (selon la demande)
A10: CA HT − frais de paiement − coûts variables par siège (IA par offre) − masse salariale (3 salariés) − support supplémentaire − CSM, maintenance et installation Enterprise − loyer − autres charges = résultat avant impôt
A11: Résultat avant impôt − IS et taxe locale sur le revenu = résultat après impôt → résultat après impôt − part de l'investisseur (6 %) = bénéfice net
A13: Spécificités coréennes (sans équivalent exact en France)
A14: • Monnaie : le won (KRW, ₩) n'a pas de centimes. 1 EUR ≈ 1 600 ₩ est une hypothèse à mettre à jour ; « Synthese » donne un repère en euros.
A15: • 연봉 (salaire annuel) : rémunération brute annuelle totale, primes et indemnités non imposables comprises (ex. indemnité repas exonérée jusqu'à 200 000 ₩/mois). Pas de 13e mois séparé.
... A42: • Non pris en compte : essai gratuit de 14 jours, remises annuelles, remboursements, rémunération des fondateurs, amortissements, aides publiques.

Sheet Synthese
A1: Synthèse — quand l'entreprise devient-elle bénéficiaire ?
A2: Se recalcule automatiquement quand vous modifiez l'onglet « Hypotheses » (notamment les sections 8 à 10).
A4: Indicateur | B4: Mois n° | C4: Date | D4: Remarque | E4: ≈ EUR
A5: Premier mois de bénéfice net | B5: =IF(MIN(Previsions!$C$46:$BJ$46)=9999,"non atteint en 60 mois",MIN(Previsions!$C$46:$BJ$46)) | C5: =IF(ISNUMBER(B5),EDATE(Hypotheses!$B$68,B5-1),"—") | D5: Premier mois où le bénéfice net (après salaires, loyer, support, CSM, IS et part de 6 %) devient positif
A6: Seuil cumulé (pertes initiales remboursées) | B6: =IF(MIN(Previsions!$C$47:$BJ$47)=9999,"non atteint en 60 mois",MIN(Previsions!$C$47:$BJ$47)) | C6: =IF(ISNUMBER(B6),EDATE(Hypotheses!$B$68,B6-1),"—") | D6: Mois où le bénéfice net cumulé redevient ≥ 0 : toutes les pertes passées sont couvertes
A7: Épuisement de la trésorerie (< 0) | B7: =IF(MIN(Previsions!$C$48:$BJ$48)=9999,"non atteint en 60 mois",MIN(Previsions!$C$48:$BJ$48)) | C7: =IF(ISNUMBER(B7),EDATE(Hypotheses!$B$68,B7-1),"—") | D7: Limite de la trésorerie de départ (après dépôt de garantie). « non atteint » = pas de manque sur 60 mois
A8: Premier besoin de support supplémentaire | B8: =IF(MIN(Previsions!$C$49:$BJ$49)=9999,"non atteint en 60 mois",MIN(Previsions!$C$49:$BJ$49)) | C8: =IF(ISNUMBER(B8),EDATE(Hypotheses!$B$68,B8-1),"—") | D8: Premier mois où le temps de support dépasse la capacité des 3 salariés
A9: Trésorerie la plus basse | B9: =MIN(Previsions!$C$44:$BJ$44) | C9: =INDEX(Previsions!$C$5:$BJ$5,MATCH(B9,Previsions!$C$44:$BJ$44,0)) | D9: Besoin de financement minimal = trésorerie de départ − trésorerie la plus basse (dépôt compris) | E9: =B9/Hypotheses!$B$13
A10: Besoin de financement minimal | B10: =MAX(0,Hypotheses!$B$73-B9) | E10: =B10/Hypotheses!$B$13
A11: Clients / sièges au premier mois bénéficiaire | B11: =IF(ISNUMBER(B5),INDEX(Previsions!$C$10:$BJ$10,B5)+INDEX(Previsions!$C$11:$BJ$11,B5),"—") | C11: =IF(ISNUMBER(B5),INDEX(Previsions!$C$17:$BJ$17,B5),"—") | D11: Clients (B, Enterprise compris) et sièges (C)
A12: Taux d'occupation maximal du support | B12: =MAX(Previsions!$C$21:$BJ$21) | D12: Au-dessus de 100 %, du renfort a été nécessaire
A13: Montants en wons (KRW). Colonnes ≈ EUR : conversion indicative au taux saisi dans « Hypotheses », section 2.
A14: Exercice | B14: Chiffre d'affaires (₩) | C14: Bénéfice net (₩) | D14: Marge nette | E14: CA ≈ EUR | F14: Bénéfice net ≈ EUR
A15: =Annuel!B4 | B15: =Annuel!B11 | C15: =Annuel!B22 | D15: =Annuel!B23 | E15: =B15/Hypotheses!$B$13 | F15: =C15/Hypotheses!$B$13
A16: =Annuel!C4 | B16: =Annuel!C11 | C16: =Annuel!C22 | D16: =Annuel!C23 | E16: =B16/Hypotheses!$B$13 | F16: =C16/Hypotheses!$B$13
A17: =Annuel!D4 | B17: =Annuel!D11 | C17: =Annuel!D22 | D17: =Annuel!D23 | E17: =B17/Hypotheses!$B$13 | F17: =C17/Hypotheses!$B$13
A18: =Annuel!E4 | B18: =Annuel!E11 | C18: =Annuel!E22 | D18: =Annuel!E23 | E18: =B18/Hypotheses!$B$13 | F18: =C18/Hypotheses!$B$13
A19: =Annuel!F4 | B19: =Annuel!F11 | C19: =Annuel!F22 | D19: =Annuel!F23 | E19: =B19/Hypotheses!$B$13 | F19: =C19/Hypotheses!$B$13

Sheet Hypotheses
A1: Hypothèses — ne modifiez que les cellules jaunes (texte bleu)
A2: Modèle COREEN traduit en français : montants en wons coréens (KRW, ₩) hors TVA, droit du travail et fiscalité de la Corée du Sud. Les valeurs d'exemple sont des hypothèses. Les notes « Corée » expliquent les dispositifs sans équivalent en France.
A4: 1. Grille tarifaire Scalyo (par siège et par mois, HT) — source : app-v2/frontend/functions/api/_config/prices.js, src/config/plans.config.js
A5: Offre | B5: KRW / siège | C5: EUR / siège | D5: USD / siège | E5: Sièges max. | F5: Prix retenu (₩/siège) | G5: Remarque
A6: Starter | B6: 139000 | C6: 79 | D6: 89 | E6: 3 | F6: =IF(Hypotheses!$B$12="EUR",C6*Hypotheses!$B$13,IF(Hypotheses!$B$12="USD",D6*Hypotheses!$B$14,B6)) | G6: Prix du code. 50 comptes clients max., 3 sièges
A7: Growth | B7: 209000 | C7: 119 | D7: 139 | E7: 7 | F7: =IF(Hypotheses!$B$12="EUR",C7*Hypotheses!$B$13,IF(Hypotheses!$B$12="USD",D7*Hypotheses!$B$14,B7)) | G7: Prix du code. Comptes clients illimités, 7 sièges
A8: Elite | B8: 279000 | C8: 159 | D8: 189 | E8: 24 | F8: =IF(Hypotheses!$B$12="EUR",C8*Hypotheses!$B$13,IF(Hypotheses!$B$12="USD",D8*Hypotheses!$B$14,B8)) | G8: Prix du code. Comptes clients illimités, 24 sièges
A9: Enterprise | B9: 279000 | C9: 159 | D9: 189 | E9: illimité | F9: =IF(Hypotheses!$B$12="EUR",C9*Hypotheses!$B$13,IF(Hypotheses!$B$12="USD",D9*Hypotheses!$B$14,B9)) | G9: Aucun prix dans le code (sur devis). Prix Elite par défaut — à remplacer par le tarif négocié
A11: 2. Conditions de chiffre d'affaires
A12: Devise de facturation | B12: KRW | G12: KRW / EUR / USD. Un client facturé en EUR ou USD est converti en wons au taux ci-dessous
A13: Taux : 1 EUR = ? ₩ | B13: 1600 | G13: Hypothèse — à mettre à jour. Sert aussi aux repères ≈ EUR de « Synthese »
A14: Taux : 1 USD = ? ₩ | B14: 1400 | G14: Hypothèse — à mettre à jour
A15: Prix affichés TTC ? | B15: HT | G15: « HT » : le prix affiché est le CA (usage B2B, 부가세 별도). « TTC » : CA = prix ÷ (1 + TVA)
A16: Taux de TVA — 부가세 | B16: 0.1 | G16: Corée : taux unique de 10 % (France : 20 %). Collectée pour l'État, ce n'est pas du CA
A17: Frais de paiement (Stripe, etc.) | B17: 0.035 | G17: Hypothèse — cartes étrangères et frais de change compris. À ajuster sur les relevés réels
A18: Part du prix reconnue en CA (TVA) | B18: =IF(Hypotheses!$B$15="TTC",1/(1+Hypotheses!$B$16),1) | G18: Calcul : part du prix affiché qui constitue du chiffre d'affaires
A20: 3. Coûts variables — par siège et par mois (plus l'offre est élevée, plus l'IA est sollicitée)
A21: Poste | B21: Starter | C21: Growth | D21: Elite | E21: Enterprise | G21: Remarque
A22: Coût IA (Mistral, etc., par siège / mois) | B22: 3000 | C22: 6000 | D22: 15000 | E22: 20000 | G22: Hypothèse — à partir d'Elite, le studio e-mail IA et les playbooks automatiques multiplient les appels IA. À ajuster sur les factures
A23: Autres coûts variables (base de données, e-mail, stockage, par siège / mois) | B23: 2000 | C23: 2000 | D23: 2000 | E23: 2000 | G23: Hypothèse — factures Supabase, Resend et stockage divisées par le nombre de sièges
A24: → Coût variable total par siège / mois | B24: =B22+B23 | C24: =C22+C23 | D24: =D22+D23 | E24: =E22+E23
A26: 4. Charges fixes mensuelles (hors masse salariale)
A27: Loyer mensuel — 월세 (charges de gestion 관리비 comprises) | B27: 1500000 | G27: Hypothèse — Corée : le loyer mensuel (월세) s'accompagne presque toujours d'un dépôt de garantie élevé (voir 4-1) et de charges de gestion de l'immeuble (관리비)
A28: Infrastructure et outils SaaS (part fixe) | B28: 500000 | G28: Hypothèse — Cloudflare, abonnements Supabase, domaines, outils collaboratifs
A29: Marketing et prospection | B29: 2000000 | G29: Hypothèse
A30: Autres (tenue comptable 세무기장, assurances, télécoms) | B30: 700000 | G30: Hypothèse — Corée : la comptabilité des PME est le plus souvent confiée à un 세무사 (conseiller fiscal agréé, rôle proche de l'expert-comptable français), pour un forfait mensuel
A31: Total charges fixes hors salaires (mois) | B31: =SUM(B27:B30)
A33: 4-1. Coûts de démarrage (une fois)
A34: Dépôt de garantie du bail — 보증금 | B34: 15000000 | G34: Sort de la trésorerie au mois 1 uniquement ; restituable, donc pas une charge (supposé non restitué sur 60 mois). Corée : souvent 10 mois de loyer ou plus, contre 3 mois habituellement en France
A35: Autres coûts de démarrage (mobilier, PC, frais de constitution) | B35: 0 | G35: Passés en charge au mois 1 (pas d'amortissement). 0 si aucun
A37: 5. Masse salariale — 3 salariés (droit du travail et cotisations coréens)
A38: Salarié | B38: Salaire annuel — 연봉 (₩) | G38: Remarque
A39: Salarié 1 | B39: 50000000 | G39: Hypothèse — Corée : le 연봉 est la rémunération brute annuelle totale, primes et indemnités non imposables comprises (ex. indemnité repas exonérée jusqu'à 200 000 ₩/mois)
A40: Salarié 2 | B40: 50000000 | G40: Hypothèse — Corée : le 연봉 est la rémunération brute annuelle totale, primes et indemnités non imposables comprises (ex. indemnité repas exonérée jusqu'à 200 000 ₩/mois)
A41: Salarié 3 | B41: 50000000 | G41: Hypothèse — Corée : le 연봉 est la rémunération brute annuelle totale, primes et indemnités non imposables comprises (ex. indemnité repas exonérée jusqu'à 200 000 ₩/mois)
A42: Total des salaires annuels | B42: =SUM(B39:B41)
A43: Charges employeur — les « 4 assurances sociales » coréennes (4대보험) et l'indemnité de départ. Taux 2026 estimés, à vérifier
A44: Pension nationale — 국민연금 (part employeur) | B44: 0.0475 | G44: Corée : régime public unique de retraite (base et complémentaire réunies). Taux total 9,5 % en 2026, partagé 50/50 ; assiette plafonnée (≈ 6,37 M₩/mois) — à vérifier
A45: Assurance maladie — 건강보험 (part employeur) | B45: 0.03595 | G45: Corée : caisse publique unique (NHIS), pas de mutuelle d'entreprise obligatoire. Taux 2026 : 7,19 % partagé 50/50 — à vérifier
A46: Assurance dépendance — 장기요양보험 (en % de la cotisation maladie) | B46: 0.1314 | G46: Corée : calculée sur la cotisation maladie, pas sur le salaire ; finance la prise en charge des personnes âgées dépendantes. Estimation 2026
...

Sheet Calculateur
A1: Calculateur de seuil de rentabilité — saisissez le nombre moyen de clients et de sièges
A2: Saisissez dans les cellules jaunes le nombre moyen de clients et de sièges par client pour chaque offre. L'IS est calculé en annualisant ce résultat mensuel (sans report déficitaire). Les coûts ponctuels (onboarding, installation) sont exclus.
A4: 1. Saisie : clients et sièges
A5: Offre | B5: Nombre moyen de clients | C5: Sièges moyens / client | D5: Total sièges | E5: Prix retenu (₩/siège) | F5: CA mensuel (₩) | G5: Marge sur coûts variables (₩) | H5: Temps de support / mois
A6: Starter | B6: 10 | C6: 2.5 | D6: =B6*C6 | E6: =Hypotheses!$F$6 | F6: =D6*E6*Hypotheses!$B$18 | G6: =F6*(1-Hypotheses!$B$17)-D6*Hypotheses!$B$24 | H6: =B6*Hypotheses!$B$91+D6*Hypotheses!$B$90 | I6: =IF(AND(ISNUMBER(Hypotheses!$E$6),C6>Hypotheses!$E$6),"⚠ sièges max. dépassés","")
A7: Growth | B7: 8 | C7: 5 | D7: =B7*C7 | E7: =Hypotheses!$F$7 | F7: =D7*E7*Hypotheses!$B$18 | G7: =F7*(1-Hypotheses!$B$17)-D7*Hypotheses!$C$24 | H7: =B7*Hypotheses!$C$91+D7*Hypotheses!$C$90 | I7: =IF(AND(ISNUMBER(Hypotheses!$E$7),C7>Hypotheses!$E$7),"⚠ sièges max. dépassés","")
A8: Elite | B8: 3 | C8: 12 | D8: =B8*C8 | E8: =Hypotheses!$F$8 | F8: =D8*E8*Hypotheses!$B$18 | G8: =F8*(1-Hypotheses!$B$17)-D8*Hypotheses!$D$24 | H8: =B8*Hypotheses!$D$91+D8*Hypotheses!$D$90 | I8: =IF(AND(ISNUMBER(Hypotheses!$E$8),C8>Hypotheses!$E$8),"⚠ sièges max. dépassés","")
A9: Enterprise | B9: 0 | C9: 50 | D9: =B9*C9 | E9: =Hypotheses!$F$9 | F9: =D9*E9*Hypotheses!$B$18 | G9: =F9*(1-Hypotheses!$B$17)-D9*Hypotheses!$E$24 | H9: CSM dédié | I9: =IF(AND(ISNUMBER(Hypotheses!$E$9),C9>Hypotheses!$E$9),"⚠ sièges max. dépassés","")
A10: Total | B10: =SUM(B6:B9) | C10: =IF(B10>0,D10/B10,0) | D10: =SUM(D6:D9) | F10: =SUM(F6:F9) | G10: =SUM(G6:G9) | H10: =SUM(H6:H9)
C11: ↑ sièges moyens par client
A13: 2. Équipe de support (offres en libre-service)
A14: Temps de support nécessaire (mois) | B14: =H10
A15: → Capacité de support de l'équipe actuelle (h / mois) | B15: =Hypotheses!$B$97
A16: Taux d'occupation du support (besoin ÷ capacité) | B16: =IF(Calculateur!$B$15>0,Calculateur!$B$14/Calculateur!$B$15,0)
A17: Chargés de support supplémentaires | B17: =IF(Hypotheses!$B$100="proportionnel",MAX(0,Calculateur!$B$14-Calculateur!$B$15)/Hypotheses!$B$99,ROUNDUP(MAX(0,Calculateur!$B$14-Calculateur!$B$15)/Hypotheses!$B$99,0))
A18: Coût mensuel du support supplémentaire | B18: =Calculateur!$B$17*Hypotheses!$B$101
A19: Nombre maximal de clients avec l'équipe actuelle | B19: =IF(H10>0,Calculateur!$B$15/(H10/SUM(B6:B8)),"—") | G19: Selon la répartition actuelle des offres. Au-delà : recrutement
A21: 3. Enterprise (installation serveur + CSM dédié)
A22: Clients Enterprise | B22: =B9
A23: CSM dédiés | B23: =B9*Hypotheses!$B$110
A24: Coût mensuel des CSM dédiés | B24: =Calculateur!$B$23*Hypotheses!$B$111
A25: Coût mensuel de maintenance des serveurs | B25: =B9*Hypotheses!$B$108
A26: Pour un client Enterprise (sièges de la cellule C9)
A27: Marge mensuelle par client | B27: =C9*E9*Hypotheses!$B$18*(1-Hypotheses!$B$17)-C9*Hypotheses!$E$24
A28: Coûts dédiés mensuels par client (CSM + maintenance) | B28: =Hypotheses!$B$110*Hypotheses!$B$111+Hypotheses!$B$108
A29: → Résultat mensuel par client | B29: =Calculateur!$B$27-Calculateur!$B$28
A30: Délai de récupération de l'installation (mois) | B30: =IF(Hypotheses!$B$106-Hypotheses!$B$107<=0,0,IF(Calculateur!$B$29>0,(Hypotheses!$B$106-Hypotheses!$B$107)/Calculateur!$B$29,"jamais récupéré")) | G30: (coût d'installation − frais facturés) ÷ résultat mensuel par client
A31: Sièges minimum pour qu'un client ne soit pas déficitaire | B31: =IF(E9*Hypotheses!$B$18*(1-Hypotheses!$B$17)-Hypotheses!$E$24>0,Calculateur!$B$28/(E9*Hypotheses!$B$18*(1-Hypotheses!$B$17)-Hypotheses!$E$24),"—") | G31: Point où le CA des sièges couvre le CSM et la maintenance
A33: 4. Compte de résultat mensuel (₩)
A34: Chiffre d'affaires HT | B34: =F10
A35: (−) Frais de paiement | B35: =-F10*Hypotheses!$B$17
A36: (−) Coûts variables par siège (IA comprise) | B36: =-(D6*Hypotheses!$B$24+D7*Hypotheses!$C$24+D8*Hypotheses!$D$24+D9*Hypotheses!$E$24)
A37: → Marge sur coûts variables | B37: =G10
A38: (−) Masse salariale (3 salariés, année 1) | B38: =-Hypotheses!$B$52
A39: (−) Support supplémentaire | B39: =-Calculateur!$B$18
A40: (−) CSM dédiés Enterprise | B40: =-Calculateur!$B$24
A41: (−) Maintenance serveurs Enterprise | B41: =-Calculateur!$B$25
A42: (−) Loyer | B42: =-Hypotheses!$B$27
A43: (−) Autres charges fixes | B43: =-(Hypotheses!$B$31-Hypotheses!$B$27)
A44: → Résultat avant impôt | B44: =Calculateur!$B$37+SUM(B38:B43)
...

Sheet Previsions
A1: Prévisions mensuelles — résultat sur 60 mois selon les hypothèses (sections 8 à 10)
A2: Tout est calculé. Modifiez l'onglet « Hypotheses ». Les nombres de clients en libre-service sont des espérances, d'où des décimales.
A4: Mois n° | C4: 1 | D4: 2 | E4: 3 | F4: 4 | G4: 5 | H4: 6 | I4: 7 | J4: 8 | K4: 9 | L4: 10 | M4: 11 | N4: 12 | O4: 13 | P4: 14 | Q4: 15 | R4: 16 | S4: 17 | T4: 18 | U4: 19 | V4: 20 | W4: 21 | X4: 22 | Y4: 23 | Z4: 24 | AA4: 25 | AB4: 26 | AC4: 27 | AD4: 28 | AE4: 29 | AF4: 30 | AG4: 31 | AH4: 32 | AI4: 33 | AJ4: 34 | AK4: 35 | AL4: 36 | AM4: 37 | AN4: 38 | AO4: 39 | AP4: 40 | AQ4: 41 | AR4: 42 | AS4: 43 | AT4: 44 | AU4: 45 | AV4: 46 | AW4: 47 | AX4: 48 | AY4: 49 | AZ4: 50 | BA4: 51 | BB4: 52 | BC4: 53 | BD4: 54 | BE4: 55 | BF4: 56 | BG4: 57 | BH4: 58 | BI4: 59 | BJ4: 60
A5: Mois | C5: =EDATE(Hypotheses!$B$68,C4-1) | D5: =EDATE(Hypotheses!$B$68,D4-1) | E5: =EDATE(Hypotheses!$B$68,E4-1) | F5: =EDATE(Hypotheses!$B$68,F4-1) | G5: =EDATE(Hypotheses!$B$68,G4-1) | H5: =EDATE(Hypotheses!$B$68,H4-1) | I5: =EDATE(Hypotheses!$B$68,I4-1) | J5: =EDATE(Hypotheses!$B$68,J4-1) | ... BJ5: =EDATE(Hypotheses!$B$68,BJ4-1)
A6: Année n° | C6: =INT((C4-1)/12)+1 | D6: =INT((D4-1)/12)+1 | E6: =INT((E4-1)/12)+1 | F6: =INT((F4-1)/12)+1 | G6: =INT((G4-1)/12)+1 | H6: =INT((H4-1)/12)+1 | I6: =INT((I4-1)/12)+1 | J6: =INT((J4-1)/12)+1 | ... BJ6: =INT((BJ4-1)/12)+1
A7: Clients
A8: Nouveaux clients (libre-service) | C8: =Hypotheses!$B$70*(1+Hypotheses!$B$71)^(C4-1) | D8: =Hypotheses!$B$70*(1+Hypotheses!$B$71)^(D4-1) | E8: =Hypotheses!$B$70*(1+Hypotheses!$B$71)^(E4-1) | F8: =Hypotheses!$B$70*(1+Hypotheses!$B$71)^(F4-1) | G8: =Hypotheses!$B$70*(1+Hypotheses!$B$71)^(G4-1) | H8: =Hypotheses!$B$70*(1+Hypotheses!$B$71)^(H4-1) | I8: =Hypotheses!$B$70*(1+Hypotheses!$B$71)^(I4-1) | J8: =Hypotheses!$B$70*(1+Hypotheses!$B$71)^(J4-1) | ... BJ8: =Hypotheses!$B$70*(1+Hypotheses!$B$71)^(BJ4-1)
A9: Clients perdus (libre-service) | C9: =Hypotheses!$B$69*Hypotheses!$B$72 | D9: =C10*Hypotheses!$B$72 | E9: =D10*Hypotheses!$B$72 | F9: =E10*Hypotheses!$B$72 | G9: =F10*Hypotheses!$B$72 | H9: =G10*Hypotheses!$B$72 | I9: =H10*Hypotheses!$B$72 | J9: =I10*Hypotheses!$B$72 | K9: =J10*Hypotheses!$B$72 | ... BJ9: =BI10*Hypotheses!$B$72
A10: Clients en fin de mois (libre-service) | C10: =Hypotheses!$B$69-C9+C8 | D10: =C10-D9+D8 | E10: =D10-E9+E8 | F10: =E10-F9+F8 | G10: =F10-G9+G8 | H10: =G10-H9+H8 | I10: =H10-I9+I8 | J10: =I10-J9+J8 | K10: =J10-K9+K8 | ... BJ10: =BI10-BJ9+BJ8
A11: Clients Enterprise | C11: =COUNTIFS(Hypotheses!$B$114:$B$118,"<="&C4,Hypotheses!$B$114:$B$118,">0") | D11: =COUNTIFS(Hypotheses!$B$114:$B$118,"<="&D4,Hypotheses!$B$114:$B$118,">0") | E11: =COUNTIFS(Hypotheses!$B$114:$B$118,"<="&E4,Hypotheses!$B$114:$B$118,">0") | F11: =COUNTIFS(Hypotheses!$B$114:$B$118,"<="&F4,Hypotheses!$B$114:$B$118,">0") | G11: =COUNTIFS(Hypotheses!$B$114:$B$118,"<="&G4,Hypotheses!$B$114:$B$118,">0") | H11: =COUNTIFS(Hypotheses!$B$114:$B$118,"<="&H4,Hypotheses!$B$114:$B$118,">0") | I11: =COUNTIFS(Hypotheses!$B$114:$B$118,"<="&I4,Hypotheses!$B$114:$B$118,">0") | J11: =COUNTIFS(Hypotheses!$B$114:$B$118,"<="&J4,Hypotheses!$B$114:$B$118,">0") | ... BJ11: =COUNTIFS(Hypotheses!$B$114:$B$118,"<="&BJ4,Hypotheses!$B$114:$B$118,">0")
A12: Nouveaux contrats Enterprise | C12: =COUNTIF(Hypotheses!$B$114:$B$118,C4) | D12: =COUNTIF(Hypotheses!$B$114:$B$118,D4) | E12: =COUNTIF(Hypotheses!$B$114:$B$118,E4) | F12: =COUNTIF(Hypotheses!$B$114:$B$118,F4) | G12: =COUNTIF(Hypotheses!$B$114:$B$118,G4) | H12: =COUNTIF(Hypotheses!$B$114:$B$118,H4) | I12: =COUNTIF(Hypotheses!$B$114:$B$118,I4) | J12: =COUNTIF(Hypotheses!$B$114:$B$118,J4) | ... BJ12: =COUNTIF(Hypotheses!$B$114:$B$118,BJ4)
A13: siège — Starter | C13: =C10*Hypotheses!$B$76*Hypotheses!$C$76 | D13: =D10*Hypotheses!$B$76*Hypotheses!$C$76 | E13: =E10*Hypotheses!$B$76*Hypotheses!$C$76 | F13: =F10*Hypotheses!$B$76*Hypotheses!$C$76 | G13: =G10*Hypotheses!$B$76*Hypotheses!$C$76 | H13: =H10*Hypotheses!$B$76*Hypotheses!$C$76 | I13: =I10*Hypotheses!$B$76*Hypotheses!$C$76 | J13: =J10*Hypotheses!$B$76*Hypotheses!$C$76 | ... BJ13: =BJ10*Hypotheses!$B$76*Hypotheses!$C$76
A14: siège — Growth | C14: =C10*Hypotheses!$B$77*Hypotheses!$C$77 | D14: =D10*Hypotheses!$B$77*Hypotheses!$C$77 | E14: =E10*Hypotheses!$B$77*Hypotheses!$C$77 | F14: =F10*Hypotheses!$B$77*Hypotheses!$C$77 | G14: =G10*Hypotheses!$B$77*Hypotheses!$C$77 | H14: =H10*Hypotheses!$B$77*Hypotheses!$C$77 | I14: =I10*Hypotheses!$B$77*Hypotheses!$C$77 | J14: =J10*Hypotheses!$B$77*Hypotheses!$C$77 | ... BJ14: =BJ10*Hypotheses!$B$77*Hypotheses!$C$77
A15: siège — Elite | C15: =C10*Hypotheses!$B$78*Hypotheses!$C$78 | D15: =D10*Hypotheses!$B$78*Hypotheses!$C$78 | E15: =E10*Hypotheses!$B$78*Hypotheses!$C$78 | F15: =F10*Hypotheses!$B$78*Hypotheses!$C$78 | G15: =G10*Hypotheses!$B$78*Hypotheses!$C$78 | H15: =H10*Hypotheses!$B$78*Hypotheses!$C$78 | I15: =I10*Hypotheses!$B$78*Hypotheses!$C$78 | J15: =J10*Hypotheses!$B$78*Hypotheses!$C$78 | ... BJ15: =BJ10*Hypotheses!$B$78*Hypotheses!$C$78
A16: siège — Enterprise | C16: =SUMIFS(Hypotheses!$C$114:$C$118,Hypotheses!$B$114:$B$118,"<="&C4,Hypotheses!$B$114:$B$118,">0") | D16: =SUMIFS(Hypotheses!$C$114:$C$118,Hypotheses!$B$114:$B$118,"<="&D4,Hypotheses!$B$114:$B$118,">0") | E16: =SUMIFS(Hypotheses!$C$114:$C$118,Hypotheses!$B$114:$B$118,"<="&E4,Hypotheses!$B$114:$B$118,">0") | F16: =SUMIFS(Hypotheses!$C$114:$C$118,Hypotheses!$B$114:$B$118,"<="&F4,Hypotheses!$B$114:$B$118,">0") | G16: =SUMIFS(Hypotheses!$C$114:$C$118,Hypotheses!$B$114:$B$118,"<="&G4,Hypotheses!$B$114:$B$118,">0") | H16: =SUMIFS(Hypotheses!$C$114:$C$118,Hypotheses!$B$114:$B$118,"<="&H4,Hypotheses!$B$114:$B$118,">0") | I16: =SUMIFS(Hypotheses!$C$114:$C$118,Hypotheses!$B$114:$B$118,"<="&I4,Hypotheses!$B$114:$B$118,">0") | J16: =SUMIFS(Hypotheses!$C$114:$C$118,Hypotheses!$B$114:$B$118,"<="&J4,Hypotheses!$B$114:$B$118,">0") | ... BJ16: =SUMIFS(Hypotheses!$C$114:$C$118,Hypotheses!$B$114:$B$118,"<="&BJ4,Hypotheses!$B$114:$B$118,">0")
A17: Total sièges | C17: =SUM(C13:C16) | D17: =SUM(D13:D16) | E17: =SUM(E13:E16) | F17: =SUM(F13:F16) | G17: =SUM(G13:G16) | H17: =SUM(H13:H16) | I17: =SUM(I13:I16) | J17: =SUM(J13:J16) | ... BJ17: =SUM(BJ13:BJ16)
A18: Support client (CS)
A19: Temps de support nécessaire (libre-service) | C19: =C10*Hypotheses!$B$76*Hypotheses!$B$91+C13*Hypotheses!$B$90+C8*Hypotheses!$B$76*Hypotheses!$B$89+C10*Hypotheses!$B$77*Hypotheses!$C$91+C14*Hypotheses!$C$90+C8*Hypotheses!$B$77*Hypotheses!$C$89+C10*Hypotheses!$B$78*Hypotheses!$D$91+C15*Hypotheses!$D$90+C8*Hypotheses!$B$78*Hypotheses!$D$89 | D19: =D10*Hypotheses!$B$76*Hypotheses!$B$91+D13*Hypotheses!$B$90+D8*Hypotheses!$B$76*Hypotheses!$B$89+D10*Hypotheses!$B$77*Hypotheses!$C$91+D14*Hypotheses!$C$90+D8*Hypotheses!$B$77*Hypotheses!$C$89+D10*Hypotheses!$B$78*Hypotheses!$D$91+D15*Hypotheses!$D$90+D8*Hypotheses!$B$78*Hypotheses!$D$89 | E19: =E10*Hypotheses!$B$76*Hypotheses!$B$91+E13*Hypotheses!$B$90+E8*Hypotheses!$B$76*Hypotheses!$B$89+E10*Hypotheses!$B$77*Hypotheses!$C$91+E14*Hypotheses!$C$90+E8*Hypotheses!$B$77*Hypotheses!$C$89+E10*Hypotheses!$B$78*Hypotheses!$D$91+E15*Hypotheses!$D$90+E8*Hypotheses!$B$78*Hypotheses!$D$89 | F19: =F10*Hypotheses!$B$76*Hypotheses!$B$91+F13*Hypotheses!$B$90+F8*Hypotheses!$B$76*Hypotheses!$B$89+F10*Hypotheses!$B$77*Hypotheses!$C$91+F14*Hypotheses!$C$90+F8*Hypotheses!$B$77*Hypotheses!$C$89+F10*Hypotheses!$B$78*Hypotheses!$D$91+F15*Hypotheses!$D$90+F8*Hypotheses!$B$78*Hypotheses!$D$89 | G19: =G10*Hypotheses!$B$76*Hypotheses!$B$91+G13*Hypotheses!$B$90+G8*Hypotheses!$B$76*Hypotheses!$B$89+G10*Hypotheses!$B$77*Hypotheses!$C$91+G14*Hypotheses!$C$90+G8*Hypotheses!$B$77*Hypotheses!$C$89+G10*Hypotheses!$B$78*Hypotheses!$D$91+G15*Hypotheses!$D$90+G8*Hypotheses!$B$78*Hypotheses!$D$89 | H19: =H10*Hypotheses!$B$76*Hypotheses!$B$91+H13*Hypotheses!$B$90+H8*Hypotheses!$B$76*Hypotheses!$B$89+H10*Hypotheses!$B$77*Hypotheses!$C$91+H14*Hypotheses!$C$90+H8*Hypotheses!$B$77*Hypotheses!$C$89+H10*Hypotheses!$B$78*Hypotheses!$D$91+H15*Hypotheses!$D$90+H8*Hypotheses!$B$78*Hypotheses!$D$89 | I19: =I10*Hypotheses!$B$76*Hypotheses!$B$91+I13*Hypotheses!$B$90+I8*Hypotheses!$B$76*Hypotheses!$B$89+I10*Hypotheses!$B$77*Hypotheses!$C$91+I14*Hypotheses!$C$90+I8*Hypotheses!$B$77*Hypotheses!$C$89+I10*Hypotheses!$B$78*Hypotheses!$D$91+I15*Hypotheses!$D$90+I8*Hypotheses!$B$78*Hypotheses!$D$89 | J19: =J10*Hypotheses!$B$76*Hypotheses!$B$91+J13*Hypotheses!$B$90+J8*Hypotheses!$B$76*Hypotheses!$B$89+J10*Hypotheses!$B$77*Hypotheses!$C$91+J14*Hypotheses!$C$90+J8*Hypotheses!$B$77*Hypotheses!$C$89+J10*Hypotheses!$B$78*Hypotheses!$D$91+J15*Hypotheses!$D$90+J8*Hypotheses!$B$78*Hypotheses!$D$89 | ... BJ19: =BJ10*Hypotheses!$B$76*Hypotheses!$B$91+BJ13*Hypotheses!$B$90+BJ8*Hypotheses!$B$76*Hypotheses!$B$89+BJ10*Hypotheses!$B$77*Hypotheses!$C$91+BJ14*Hypotheses!$C$90+BJ8*Hypotheses!$B$77*Hypotheses!$C$89+BJ10*Hypotheses!$B$78*Hypotheses!$D$91+BJ15*Hypotheses!$D$90+BJ8*Hypotheses!$B$78*Hypotheses!$D$89
A20: Capacité de l'équipe actuelle | C20: =Hypotheses!$B$97 | D20: =Hypotheses!$B$97 | E20: =Hypotheses!$B$97 | F20: =Hypotheses!$B$97 | G20: =Hypotheses!$B$97 | H20: =Hypotheses!$B$97 | I20: =Hypotheses!$B$97 | J20: =Hypotheses!$B$97 | ... BJ20: =Hypotheses!$B$97
A21: Taux d'occupation du support | C21: =IF(C20>0,C19/C20,0) | D21: =IF(D20>0,D19/D20,0) | E21: =IF(E20>0,E19/E20,0) | F21: =IF(F20>0,F19/F20,0) | G21: =IF(G20>0,G19/G20,0) | H21: =IF(H20>0,H19/H20,0) | I21: =IF(I20>0,I19/I20,0) | J21: =IF(J20>0,J19/J20,0) | ... BJ21: =IF(BJ20>0,BJ19/BJ20,0)
A22: Chargés de support supplémentaires | C22: =IF(Hypotheses!$B$100="proportionnel",MAX(0,C19-C20)/Hypotheses!$B$99,ROUNDUP(MAX(0,C19-C20)/Hypotheses!$B$99,0)) | D22: =IF(Hypotheses!$B$100="proportionnel",MAX(0,D19-D20)/Hypotheses!$B$99,ROUNDUP(MAX(0,D19-D20)/Hypotheses!$B$99,0)) | E22: =IF(Hypotheses!$B$100="proportionnel",MAX(0,E19-E20)/Hypotheses!$B$99,ROUNDUP(MAX(0,E19-E20)/Hypotheses!$B$99,0)) | F22: =IF(Hypotheses!$B$100="proportionnel",MAX(0,F19-F20)/Hypotheses!$B$99,ROUNDUP(MAX(0,F19-F20)/Hypotheses!$B$99,0)) | G22: =IF(Hypotheses!$B$100="proportionnel",MAX(0,G19-G20)/Hypotheses!$B$99,ROUNDUP(MAX(0,G19-G20)/Hypotheses!$B$99,0)) | H22: =IF(Hypotheses!$B$100="proportionnel",MAX(0,H19-H20)/Hypotheses!$B$99,ROUNDUP(MAX(0,H19-H20)/Hypotheses!$B$99,0)) | I22: =IF(Hypotheses!$B$100="proportionnel",MAX(0,I19-I20)/Hypotheses!$B$99,ROUNDUP(MAX(0,I19-I20)/Hypotheses!$B$99,0)) | J22: =IF(Hypotheses!$B$100="proportionnel",MAX(0,J19-J20)/Hypotheses!$B$99,ROUNDUP(MAX(0,J19-J20)/Hypotheses!$B$99,0)) | ... BJ22: =IF(Hypotheses!$B$100="proportionnel",MAX(0,BJ19-BJ20)/Hypotheses!$B$99,ROUNDUP(MAX(0,BJ19-BJ20)/Hypotheses!$B$99,0))
A23: CSM dédiés Enterprise | C23: =SUMIFS(Hypotheses!$D$114:$D$118,Hypotheses!$B$114:$B$118,"<="&C4,Hypotheses!$B$114:$B$118,">0") | D23: =SUMIFS(Hypotheses!$D$114:$D$118,Hypotheses!$B$114:$B$118,"<="&D4,Hypotheses!$B$114:$B$118,">0") | E23: =SUMIFS(Hypotheses!$D$114:$D$118,Hypotheses!$B$114:$B$118,"<="&E4,Hypotheses!$B$114:$B$118,">0") | F23: =SUMIFS(Hypotheses!$D$114:$D$118,Hypotheses!$B$114:$B$118,"<="&F4,Hypotheses!$B$114:$B$118,">0") | G23: =SUMIFS(Hypotheses!$D$114:$D$118,Hypotheses!$B$114:$B$118,"<="&G4,Hypotheses!$B$114:$B$118,">0") | H23: =SUMIFS(Hypotheses!$D$114:$D$118,Hypotheses!$B$114:$B$118,"<="&H4,Hypotheses!$B$114:$B$118,">0") | I23: =SUMIFS(Hypotheses!$D$114:$D$118,Hypotheses!$B$114:$B$118,"<="&I4,Hypotheses!$B$114:$B$118,">0") | J23: =SUMIFS(Hypotheses!$D$114:$D$118,Hypotheses!$B$114:$B$118,"<="&J4,Hypotheses!$B$114:$B$118,">0") | ... BJ23: =SUMIFS(Hypotheses!$D$114:$D$118,Hypotheses!$B$114:$B$118,"<="&BJ4,Hypotheses!$B$114:$B$118,">0")
A24: Compte de résultat (₩)
A25: Chiffre d'affaires HT | C25: =(C13*Hypotheses!$F$6+C14*Hypotheses!$F$7+C15*Hypotheses!$F$8+C16*Hypotheses!$F$9)*Hypotheses!$B$18 | D25: =(D13*Hypotheses!$F$6+D14*Hypotheses!$F$7+D15*Hypotheses!$F$8+D16*Hypotheses!$F$9)*Hypotheses!$B$18 | E25: =(E13*Hypotheses!$F$6+E14*Hypotheses!$F$7+E15*Hypotheses!$F$8+E16*Hypotheses!$F$9)*Hypotheses!$B$18 | F25: =(F13*Hypotheses!$F$6+F14*Hypotheses!$F$7+F15*Hypotheses!$F$8+F16*Hypotheses!$F$9)*Hypotheses!$B$18 | G25: =(G13*Hypotheses!$F$6+G14*Hypotheses!$F$7+G15*Hypotheses!$F$8+G16*Hypotheses!$F$9)*Hypotheses!$B$18 | H25: =(H13*Hypotheses!$F$6+H14*Hypotheses!$F$7+H15*Hypotheses!$F$8+H16*Hypotheses!$F$9)*Hypotheses!$B$18 | I25: =(I13*Hypotheses!$F$6+I14*Hypotheses!$F$7+I15*Hypotheses!$F$8+I16*Hypotheses!$F$9)*Hypotheses!$B$18 | J25: =(J13*Hypotheses!$F$6+J14*Hypotheses!$F$7+J15*Hypotheses!$F$8+J16*Hypotheses!$F$9)*Hypotheses!$B$18 | ... BJ25: =(BJ13*Hypotheses!$F$6+BJ14*Hypotheses!$F$7+BJ15*Hypotheses!$F$8+BJ16*Hypotheses!$F$9)*Hypotheses!$B$18
A26: Frais d'installation facturés (Enterprise) | C26: =C12*Hypotheses!$B$107 | D26: =D12*Hypotheses!$B$107 | E26: =E12*Hypotheses!$B$107 | F26: =F12*Hypotheses!$B$107 | G26: =G12*Hypotheses!$B$107 | H26: =H12*Hypotheses!$B$107 | I26: =I12*Hypotheses!$B$107 | J26: =J12*Hypotheses!$B$107 | ... BJ26: =BJ12*Hypotheses!$B$107
A27: (−) Frais de paiement | C27: =-C25*Hypotheses!$B$17 | D27: =-D25*Hypotheses!$B$17 | E27: =-E25*Hypotheses!$B$17 | F27: =-F25*Hypotheses!$B$17 | G27: =-G25*Hypotheses!$B$17 | H27: =-H25*Hypotheses!$B$17 | I27: =-I25*Hypotheses!$B$17 | J27: =-J25*Hypotheses!$B$17 | ... BJ27: =-BJ25*Hypotheses!$B$17
A28: (−) Coûts variables par siège (IA comprise) | C28: =-(C13*Hypotheses!$B$24+C14*Hypotheses!$C$24+C15*Hypotheses!$D$24+C16*Hypotheses!$E$24) | D28: =-(D13*Hypotheses!$B$24+D14*Hypotheses!$C$24+D15*Hypotheses!$D$24+D16*Hypotheses!$E$24) | E28: =-(E13*Hypotheses!$B$24+E14*Hypotheses!$C$24+E15*Hypotheses!$D$24+E16*Hypotheses!$E$24) | F28: =-(F13*Hypotheses!$B$24+F14*Hypotheses!$C$24+F15*Hypotheses!$D$24+F16*Hypotheses!$E$24) | G28: =-(G13*Hypotheses!$B$24+G14*Hypotheses!$C$24+G15*Hypotheses!$D$24+G16*Hypotheses!$E$24) | H28: =-(H13*Hypotheses!$B$24+H14*Hypotheses!$C$24+H15*Hypotheses!$D$24+H16*Hypotheses!$E$24) | I28: =-(I13*Hypotheses!$B$24+I14*Hypotheses!$C$24+I15*Hypotheses!$D$24+I16*Hypotheses!$E$24) | J28: =-(J13*Hypotheses!$B$24+J14*Hypotheses!$C$24+J15*Hypotheses!$D$24+J16*Hypotheses!$E$24) | ... BJ28: =-(BJ13*Hypotheses!$B$24+BJ14*Hypotheses!$C$24+BJ15*Hypotheses!$D$24+BJ16*Hypotheses!$E$24)
A29: → Marge sur coûts variables | C29: =C25+C26+C27+C28 | D29: =D25+D26+D27+D28 | E29: =E25+E26+E27+E28 | F29: =F25+F26+F27+F28 | G29: =G25+G26+G27+G28 | H29: =H25+H26+H27+H28 | I29: =I25+I26+I27+I28 | J29: =J25+J26+J27+J28 | ... BJ29: =BJ25+BJ26+BJ27+BJ28
A30: (−) Masse salariale (3 salariés) | C30: =-Hypotheses!$B$52*(1+Hypotheses!$B$50)^(C6-1) | D30: =-Hypotheses!$B$52*(1+Hypotheses!$B$50)^(D6-1) | E30: =-Hypotheses!$B$52*(1+Hypotheses!$B$50)^(E6-1) | F30: =-Hypotheses!$B$52*(1+Hypotheses!$B$50)^(F6-1) | G30: =-Hypotheses!$B$52*(1+Hypotheses!$B$50)^(G6-1) | H30: =-Hypotheses!$B$52*(1+Hypotheses!$B$50)^(H6-1) | I30: =-Hypotheses!$B$52*(1+Hypotheses!$B$50)^(I6-1) | J30: =-Hypotheses!$B$52*(1+Hypotheses!$B$50)^(J6-1) | ... BJ30: =-Hypotheses!$B$52*(1+Hypotheses!$B$50)^(BJ6-1)
A31: (−) Support supplémentaire | C31: =-C22*Hypotheses!$B$101*(1+Hypotheses!$B$50)^(C6-1) | D31: =-D22*Hypotheses!$B$101*(1+Hypotheses!$B$50)^(D6-1) | E31: =-E22*Hypotheses!$B$101*(1+Hypotheses!$B$50)^(E6-1) | F31: =-F22*Hypotheses!$B$101*(1+Hypotheses!$B$50)^(F6-1) | G31: =-G22*Hypotheses!$B$101*(1+Hypotheses!$B$50)^(G6-1) | H31: =-H22*Hypotheses!$B$101*(1+Hypotheses!$B$50)^(H6-1) | I31: =-I22*Hypotheses!$B$101*(1+Hypotheses!$B$50)^(I6-1) | J31: =-J22*Hypotheses!$B$101*(1+Hypotheses!$B$50)^(J6-1) | ... BJ31: =-BJ22*Hypotheses!$B$101*(1+Hypotheses!$B$50)^(BJ6-1)
A32: (−) CSM dédiés Enterprise | C32: =-C23*Hypotheses!$B$111*(1+Hypotheses!$B$50)^(C6-1) | D32: =-D23*Hypotheses!$B$111*(1+Hypotheses!$B$50)^(D6-1) | E32: =-E23*Hypotheses!$B$111*(1+Hypotheses!$B$50)^(E6-1) | F32: =-F23*Hypotheses!$B$111*(1+Hypotheses!$B$50)^(F6-1) | G32: =-G23*Hypotheses!$B$111*(1+Hypotheses!$B$50)^(G6-1) | H32: =-H23*Hypotheses!$B$111*(1+Hypotheses!$B$50)^(H6-1) | I32: =-I23*Hypotheses!$B$111*(1+Hypotheses!$B$50)^(I6-1) | J32: =-J23*Hypotheses!$B$111*(1+Hypotheses!$B$50)^(J6-1) | ... BJ32: =-BJ23*Hypotheses!$B$111*(1+Hypotheses!$B$50)^(BJ6-1)
A33: (−) Maintenance serveurs Enterprise | C33: =-C11*Hypotheses!$B$108 | D33: =-D11*Hypotheses!$B$108 | E33: =-E11*Hypotheses!$B$108 | F33: =-F11*Hypotheses!$B$108 | G33: =-G11*Hypotheses!$B$108 | H33: =-H11*Hypotheses!$B$108 | I33: =-I11*Hypotheses!$B$108 | J33: =-J11*Hypotheses!$B$108 | ... BJ33: =-BJ11*Hypotheses!$B$108
A34: (−) Installation serveur Enterprise (une fois) | C34: =-C12*Hypotheses!$B$106 | D34: =-D12*Hypotheses!$B$106 | E34: =-E12*Hypotheses!$B$106 | F34: =-F12*Hypotheses!$B$106 | G34: =-G12*Hypotheses!$B$106 | H34: =-H12*Hypotheses!$B$106 | I34: =-I12*Hypotheses!$B$106 | J34: =-J12*Hypotheses!$B$106 | ... BJ34: =-BJ12*Hypotheses!$B$106
A35: (−) Autres coûts de démarrage (une fois) | C35: =IF(C4=1,-Hypotheses!$B$35,0) | D35: =IF(D4=1,-Hypotheses!$B$35,0) | E35: =IF(E4=1,-Hypotheses!$B$35,0) | F35: =IF(F4=1,-Hypotheses!$B$35,0) | G35: =IF(G4=1,-Hypotheses!$B$35,0) | H35: =IF(H4=1,-Hypotheses!$B$35,0) | I35: =IF(I4=1,-Hypotheses!$B$35,0) | J35: =IF(J4=1,-Hypotheses!$B$35,0) | ... BJ35: =IF(BJ4=1,-Hypotheses!$B$35,0)
A36: (−) Loyer | C36: =-Hypotheses!$B$27 | D36: =-Hypotheses!$B$27 | E36: =-Hypotheses!$B$27 | F36: =-Hypotheses!$B$27 | G36: =-Hypotheses!$B$27 | H36: =-Hypotheses!$B$27 | I36: =-Hypotheses!$B$27 | J36: =-Hypotheses!$B$27 | ... BJ36: =-Hypotheses!$B$27
A37: (−) Autres charges fixes | C37: =-(Hypotheses!$B$31-Hypotheses!$B$27) | D37: =-(Hypotheses!$B$31-Hypotheses!$B$27) | E37: =-(Hypotheses!$B$31-Hypotheses!$B$27) | F37: =-(Hypotheses!$B$31-Hypotheses!$B$27) | G37: =-(Hypotheses!$B$31-Hypotheses!$B$27) | H37: =-(Hypotheses!$B$31-Hypotheses!$B$27) | I37: =-(Hypotheses!$B$31-Hypotheses!$B$27) | J37: =-(Hypotheses!$B$31-Hypotheses!$B$27) | ... BJ37: =-(Hypotheses!$B$31-Hypotheses!$B$27)
A38: → Résultat avant impôt | C38: =SUM(C29:C37) | D38: =SUM(D29:D37) | E38: =SUM(E29:E37) | F38: =SUM(F29:F37) | G38: =SUM(G29:G37) | H38: =SUM(H29:H37) | I38: =SUM(I29:I37) | J38: =SUM(J29:J37) | ... BJ38: =SUM(BJ29:BJ37)
A39: (−) IS + taxe locale (impôt annuel réparti) | C39: =-IF(INDEX(Annuel!$B$24:$F$24,C6)>0,INDEX(Annuel!$B$18:$F$18,C6)*IF(C38>0,C38/INDEX(Annuel!$B$24:$F$24,C6),0),0) | D39: =-IF(INDEX(Annuel!$B$24:$F$24,D6)>0,INDEX(Annuel!$B$18:$F$18,D6)*IF(D38>0,D38/INDEX(Annuel!$B$24:$F$24,D6),0),0) | E39: =-IF(INDEX(Annuel!$B$24:$F$24,E6)>0,INDEX(Annuel!$B$18:$F$18,E6)*IF(E38>0,E38/INDEX(Annuel!$B$24:$F$24,E6),0),0) | F39: =-IF(INDEX(Annuel!$B$24:$F$24,F6)>0,INDEX(Annuel!$B$18:$F$18,F6)*IF(F38>0,F38/INDEX(Annuel!$B$24:$F$24,F6),0),0) | G39: =-IF(INDEX(Annuel!$B$24:$F$24,G6)>0,INDEX(Annuel!$B$18:$F$18,G6)*IF(G38>0,G38/INDEX(Annuel!$B$24:$F$24,G6),0),0) | H39: =-IF(INDEX(Annuel!$B$24:$F$24,H6)>0,INDEX(Annuel!$B$18:$F$18,H6)*IF(H38>0,H38/INDEX(Annuel!$B$24:$F$24,H6),0),0) | I39: =-IF(INDEX(Annuel!$B$24:$F$24,I6)>0,INDEX(Annuel!$B$18:$F$18,I6)*IF(I38>0,I38/INDEX(Annuel!$B$24:$F$24,I6),0),0) | J39: =-IF(INDEX(Annuel!$B$24:$F$24,J6)>0,INDEX(Annuel!$B$18:$F$18,J6)*IF(J38>0,J38/INDEX(Annuel!$B$24:$F$24,J6),0),0) | ... BJ39: =-IF(INDEX(Annuel!$B$24:$F$24,BJ6)>0,INDEX(Annuel!$B$18:$F$18,BJ6)*IF(BJ38>0,BJ38/INDEX(Annuel!$B$24:$F$24,BJ6),0),0)
A40: (−) Part investisseur 6 % (annuelle répartie) | C40: =-IF(INDEX(Annuel!$B$24:$F$24,C6)>0,INDEX(Annuel!$B$21:$F$21,C6)*IF(C38>0,C38/INDEX(Annuel!$B$24:$F$24,C6),0),0) | D40: =-IF(INDEX(Annuel!$B$24:$F$24,D6)>0,INDEX(Annuel!$B$21:$F$21,D6)*IF(D38>0,D38/INDEX(Annuel!$B$24:$F$24,D6),0),0) | E40: =-IF(INDEX(Annuel!$B$24:$F$24,E6)>0,INDEX(Annuel!$B$21:$F$21,E6)*IF(E38>0,E38/INDEX(Annuel!$B$24:$F$24,E6),0),0) | F40: =-IF(INDEX(Annuel!$B$24:$F$24,F6)>0,INDEX(Annuel!$B$21:$F$21,F6)*IF(F38>0,F38/INDEX(Annuel!$B$24:$F$24,F6),0),0) | G40: =-IF(INDEX(Annuel!$B$24:$F$24,G6)>0,INDEX(Annuel!$B$21:$F$21,G6)*IF(G38>0,G38/INDEX(Annuel!$B$24:$F$24,G6),0),0) | H40: =-IF(INDEX(Annuel!$B$24:$F$24,H6)>0,INDEX(Annuel!$B$21:$F$21,H6)*IF(H38>0,H38/INDEX(Annuel!$B$24:$F$24,H6),0),0) | I40: =-IF(INDEX(Annuel!$B$24:$F$24,I6)>0,INDEX(Annuel!$B$21:$F$21,I6)*IF(I38>0,I38/INDEX(Annuel!$B$24:$F$24,I6),0),0) | J40: =-IF(INDEX(Annuel!$B$24:$F$24,J6)>0,INDEX(Annuel!$B$21:$F$21,J6)*IF(J38>0,J38/INDEX(Annuel!$B$24:$F$24,J6),0),0) | ... BJ40: =-IF(INDEX(Annuel!$B$24:$F$24,BJ6)>0,INDEX(Annuel!$B$21:$F$21,BJ6)*IF(BJ38>0,BJ38/INDEX(Annuel!$B$24:$F$24,BJ6),0),0)
A41: → Bénéfice net | C41: =C38+C39+C40 | D41: =D38+D39+D40 | E41: =E38+E39+E40 | F41: =F38+F39+F40 | G41: =G38+G39+G40 | H41: =H38+H39+H40 | I41: =I38+I39+I40 | J41: =J38+J39+J40 | ... BJ41: =BJ38+BJ39+BJ40
...

Sheet Annuel
A1: Synthèse annuelle — IS et part de l'investisseur calculés par exercice
A2: Exercice = 12 mois à partir du premier mois (simplification). IS coréen : barème progressif + taxe locale sur le revenu (10 % de l'IS), report des déficits (100 % du bénéfice pour une PME).
A4: Exercice | B4: 1 | C4: 2 | D4: 3 | E4: 4 | F4: 5
A5: Premier mois | B5: =EDATE(Hypotheses!$B$68,12*(B4-1)) | C5: =EDATE(Hypotheses!$B$68,12*(C4-1)) | D5: =EDATE(Hypotheses!$B$68,12*(D4-1)) | E5: =EDATE(Hypotheses!$B$68,12*(E4-1)) | F5: =EDATE(Hypotheses!$B$68,12*(F4-1))
A6: Clients en libre-service en fin d'exercice | B6: =INDEX(Previsions!$C$10:$BJ$10,12*B4) | C6: =INDEX(Previsions!$C$10:$BJ$10,12*C4) | D6: =INDEX(Previsions!$C$10:$BJ$10,12*D4) | E6: =INDEX(Previsions!$C$10:$BJ$10,12*E4) | F6: =INDEX(Previsions!$C$10:$BJ$10,12*F4)
A7: Clients Enterprise en fin d'exercice | B7: =INDEX(Previsions!$C$11:$BJ$11,12*B4) | C7: =INDEX(Previsions!$C$11:$BJ$11,12*C4) | D7: =INDEX(Previsions!$C$11:$BJ$11,12*D4) | E7: =INDEX(Previsions!$C$11:$BJ$11,12*E4) | F7: =INDEX(Previsions!$C$11:$BJ$11,12*F4)
A8: Sièges en fin d'exercice | B8: =INDEX(Previsions!$C$17:$BJ$17,12*B4) | C8: =INDEX(Previsions!$C$17:$BJ$17,12*C4) | D8: =INDEX(Previsions!$C$17:$BJ$17,12*D4) | E8: =INDEX(Previsions!$C$17:$BJ$17,12*E4) | F8: =INDEX(Previsions!$C$17:$BJ$17,12*F4)
A9: Chargés de support supplémentaires en fin d'exercice | B9: =INDEX(Previsions!$C$22:$BJ$22,12*B4) | C9: =INDEX(Previsions!$C$22:$BJ$22,12*C4) | D9: =INDEX(Previsions!$C$22:$BJ$22,12*D4) | E9: =INDEX(Previsions!$C$22:$BJ$22,12*E4) | F9: =INDEX(Previsions!$C$22:$BJ$22,12*F4)
A10: CSM dédiés en fin d'exercice | B10: =INDEX(Previsions!$C$23:$BJ$23,12*B4) | C10: =INDEX(Previsions!$C$23:$BJ$23,12*C4) | D10: =INDEX(Previsions!$C$23:$BJ$23,12*D4) | E10: =INDEX(Previsions!$C$23:$BJ$23,12*E4) | F10: =INDEX(Previsions!$C$23:$BJ$23,12*F4)
A11: Chiffre d'affaires HT (frais d'installation compris) | B11: =SUMIF(Previsions!$C$6:$BJ$6,B4,Previsions!$C$25:$BJ$25)+SUMIF(Previsions!$C$6:$BJ$6,B4,Previsions!$C$26:$BJ$26) | C11: =SUMIF(Previsions!$C$6:$BJ$6,C4,Previsions!$C$25:$BJ$25)+SUMIF(Previsions!$C$6:$BJ$6,C4,Previsions!$C$26:$BJ$26) | D11: =SUMIF(Previsions!$C$6:$BJ$6,D4,Previsions!$C$25:$BJ$25)+SUMIF(Previsions!$C$6:$BJ$6,D4,Previsions!$C$26:$BJ$26) | E11: =SUMIF(Previsions!$C$6:$BJ$6,E4,Previsions!$C$25:$BJ$25)+SUMIF(Previsions!$C$6:$BJ$6,E4,Previsions!$C$26:$BJ$26) | F11: =SUMIF(Previsions!$C$6:$BJ$6,F4,Previsions!$C$25:$BJ$25)+SUMIF(Previsions!$C$6:$BJ$6,F4,Previsions!$C$26:$BJ$26)
A12: Marge sur coûts variables | B12: =SUMIF(Previsions!$C$6:$BJ$6,B4,Previsions!$C$29:$BJ$29) | C12: =SUMIF(Previsions!$C$6:$BJ$6,C4,Previsions!$C$29:$BJ$29) | D12: =SUMIF(Previsions!$C$6:$BJ$6,D4,Previsions!$C$29:$BJ$29) | E12: =SUMIF(Previsions!$C$6:$BJ$6,E4,Previsions!$C$29:$BJ$29) | F12: =SUMIF(Previsions!$C$6:$BJ$6,F4,Previsions!$C$29:$BJ$29)
A13: (−) Charges fixes, équipes et installations | B13: =B14-B12 | C13: =C14-C12 | D13: =D14-D12 | E13: =E14-E12 | F13: =F14-F12
A14: → Résultat avant impôt | B14: =SUMIF(Previsions!$C$6:$BJ$6,B4,Previsions!$C$38:$BJ$38) | C14: =SUMIF(Previsions!$C$6:$BJ$6,C4,Previsions!$C$38:$BJ$38) | D14: =SUMIF(Previsions!$C$6:$BJ$6,D4,Previsions!$C$38:$BJ$38) | E14: =SUMIF(Previsions!$C$6:$BJ$6,E4,Previsions!$C$38:$BJ$38) | F14: =SUMIF(Previsions!$C$6:$BJ$6,F4,Previsions!$C$38:$BJ$38)
A15: Déficits reportables à l'ouverture | B15: 0 | C15: =B19 | D15: =C19 | E15: =D19 | F15: =E19
A16: Déficits imputés | B16: =MIN(B15,MAX(0,B14)*Hypotheses!$B$62) | C16: =MIN(C15,MAX(0,C14)*Hypotheses!$B$62) | D16: =MIN(D15,MAX(0,D14)*Hypotheses!$B$62) | E16: =MIN(E15,MAX(0,E14)*Hypotheses!$B$62) | F16: =MIN(F15,MAX(0,F14)*Hypotheses!$B$62)
A17: Résultat fiscal imposable | B17: =MAX(0,B14-B16) | C17: =MAX(0,C14-C16) | D17: =MAX(0,D14-D16) | E17: =MAX(0,E14-E16) | F17: =MAX(0,F14-F16)
A18: IS + taxe locale sur le revenu (exonération déduite) | B18: =(MIN(B17,Hypotheses!$A$56)*Hypotheses!$B$56+MAX(0,MIN(B17,Hypotheses!$A$57)-Hypotheses!$A$56)*Hypotheses!$B$57+MAX(0,MIN(B17,Hypotheses!$A$58)-Hypotheses!$A$57)*Hypotheses!$B$58+MAX(0,B17-Hypotheses!$A$58)*Hypotheses!$B$59)*(1+Hypotheses!$B$60)*(1-Hypotheses!$B$61) | C18: =(MIN(C17,Hypotheses!$A$56)*Hypotheses!$B$56+MAX(0,MIN(C17,Hypotheses!$A$57)-Hypotheses!$A$56)*Hypotheses!$B$57+MAX(0,MIN(C17,Hypotheses!$A$58)-Hypotheses!$A$57)*Hypotheses!$B$58+MAX(0,C17-Hypotheses!$A$58)*Hypotheses!$B$59)*(1+Hypotheses!$B$60)*(1-Hypotheses!$B$61) | D18: =(MIN(D17,Hypotheses!$A$56)*Hypotheses!$B$56+MAX(0,MIN(D17,Hypotheses!$A$57)-Hypotheses!$A$56)*Hypotheses!$B$57+MAX(0,MIN(D17,Hypotheses!$A$58)-Hypotheses!$A$57)*Hypotheses!$B$58+MAX(0,D17-Hypotheses!$A$58)*Hypotheses!$B$59)*(1+Hypotheses!$B$60)*(1-Hypotheses!$B$61) | E18: =(MIN(E17,Hypotheses!$A$56)*Hypotheses!$B$56+MAX(0,MIN(E17,Hypotheses!$A$57)-Hypotheses!$A$56)*Hypotheses!$B$57+MAX(0,MIN(E17,Hypotheses!$A$58)-Hypotheses!$A$57)*Hypotheses!$B$58+MAX(0,E17-Hypotheses!$A$58)*Hypotheses!$B$59)*(1+Hypotheses!$B$60)*(1-Hypotheses!$B$61) | F18: =(MIN(F17,Hypotheses!$A$56)*Hypotheses!$B$56+MAX(0,MIN(F17,Hypotheses!$A$57)-Hypotheses!$A$56)*Hypotheses!$B$57+MAX(0,MIN(F17,Hypotheses!$A$58)-Hypotheses!$A$57)*Hypotheses!$B$58+MAX(0,F17-Hypotheses!$A$58)*Hypotheses!$B$59)*(1+Hypotheses!$B$60)*(1-Hypotheses!$B$61)
A19: Déficits reportables à la clôture | B19: =B15-B16+MAX(0,-B14) | C19: =C15-C16+MAX(0,-C14) | D19: =D15-D16+MAX(0,-D14) | E19: =E15-E16+MAX(0,-E14) | F19: =F15-F16+MAX(0,-F14)
A20: → Résultat après impôt | B20: =B14-B18 | C20: =C14-C18 | D20: =D14-D18 | E20: =E14-E18 | F20: =F14-F18
A21: (−) Part de l'investisseur (6 %) | B21: =MAX(0,B20)*Hypotheses!$B$65 | C21: =MAX(0,C20)*Hypotheses!$B$65 | D21: =MAX(0,D20)*Hypotheses!$B$65 | E21: =MAX(0,E20)*Hypotheses!$B$65 | F21: =MAX(0,F20)*Hypotheses!$B$65
A22: → Bénéfice net | B22: =B20-B21 | C22: =C20-C21 | D22: =D20-D21 | E22: =E20-E21 | F22: =F20-F21
A23: Marge nette | B23: =IF(B11>0,B22/B11,0) | C23: =IF(C11>0,C22/C11,0) | D23: =IF(D11>0,D22/D11,0) | E23: =IF(E11>0,E22/E11,0) | F23: =IF(F11>0,F22/F11,0)
A24: Clé de répartition : résultat des mois bénéficiaires | B24: =SUMIFS(Previsions!$C$38:$BJ$38,Previsions!$C$6:$BJ$6,B4,Previsions!$C$38:$BJ$38,">0") | C24: =SUMIFS(Previsions!$C$38:$BJ$38,Previsions!$C$6:$BJ$6,C4,Previsions!$C$38:$BJ$38,">0") | D24: =SUMIFS(Previsions!$C$38:$BJ$38,Previsions!$C$6:$BJ$6,D4,Previsions!$C$38:$BJ$38,">0") | E24: =SUMIFS(Previsions!$C$38:$BJ$38,Previsions!$C$6:$BJ$6,E4,Previsions!$C$38:$BJ$38,">0") | F24: =SUMIFS(Previsions!$C$38:$BJ$38,Previsions!$C$6:$BJ$6,F4,Previsions!$C$38:$BJ$38,">0")
A26: Note : l'IS et la part de l'investisseur annuels sont répartis sur les mois bénéficiaires de l'exercice, au prorata du résultat. Exercice en perte : 0.
A27: Note : juridiquement, la part de 6 % de l'investisseur n'est pas une charge mais une distribution (dividende). Elle est déduite ici, comme demandé, pour isoler le bénéfice revenant aux fondateurs.
