Workbook

Sheet 사용안내
A1: Scalyo 손익분기 시뮬레이터
A2: 작성 기준일: 2026-09-24 · 요금은 코드(functions/api/_config/prices.js) 기준 seat당 월 과금
A4: 무엇을 알 수 있나
A5: ① ‘손익분기계산기’: 평균 고객사 수 × 고객사당 seat 수를 넣으면 월 순이익, 필요한 CS 인력, Enterprise 1곳당 이익, 손익분기 고객사·seat 수가 나옵니다.
A6: ② ‘결과요약’: 성장 가정대로 가면 언제 월 순이익 흑자·누적 손익분기·자금 소진·추가 CS 채용이 오는지 보여줍니다.
A7: ③ ‘월별전망’ / ‘연도별요약’: 60개월 월별 손익과 5개년 요약 (법인세 누진세율·이월결손금 반영).
A9: 순이익 정의 (요청 기준)
A10: 매출 − 결제 수수료 − seat 변동비(플랜별 AI 비용 포함) − 인건비(직원 3명) − 추가 CS 인력 − Enterprise 전담 CSM·유지보수·구축비 − 월세 − 기타 고정비 = 세전이익
A11: 세전이익 − 법인세·지방소득세 = 세후이익 → 세후이익 − 투자자 지분 6% = 순이익
A13: 플랜별로 달라지는 비용
A14: • AI 비용: seat당 월 비용을 플랜별로 입력. Elite부터 AI 이메일 스튜디오·자동 플레이북 때문에 크게 늘어납니다.
A15: • 고객 대응 시간: 이메일(seat 단위), 전화·정기 미팅(고객사 단위), 온보딩(신규 1회). 높은 플랜일수록 많습니다. 기존 3명이 감당 못 하면 추가 CS 인력이 자동으로 비용에 들어갑니다.
... A35: • 14일 무료체험, 연간 할인, 환불, 창업자 급여, 감가상각, 정부지원금은 반영하지 않았습니다.

Sheet 결과요약
A1: 결과 요약 — 언제 순이익이 나는가
A2: ‘입력값’ 시트의 가정(특히 8~10번)을 바꾸면 자동으로 다시 계산됩니다.
A4: 지표 | B4: 개월차 | C4: 시점 | D4: 비고
A5: 첫 월 순이익 흑자 | B5: =IF(MIN(월별전망!$C$46:$BJ$46)=9999,"60개월 내 없음",MIN(월별전망!$C$46:$BJ$46)) | C5: =IF(ISNUMBER(B5),EDATE(입력값!$B$67,B5-1),"—") | D5: 세금·투자자 6%·인건비·월세·CS·전담 CSM을 모두 뺀 월 순이익이 처음 0보다 커지는 달
A6: 누적 손익분기 (초기 적자 전액 회수) | B6: =IF(MIN(월별전망!$C$47:$BJ$47)=9999,"60개월 내 없음",MIN(월별전망!$C$47:$BJ$47)) | C6: =IF(ISNUMBER(B6),EDATE(입력값!$B$67,B6-1),"—") | D6: 그동안의 누적 적자를 모두 메워 누적 순이익이 0 이상이 되는 달
A7: 현금 소진 (현금 잔액 < 0) | B7: =IF(MIN(월별전망!$C$48:$BJ$48)=9999,"60개월 내 없음",MIN(월별전망!$C$48:$BJ$48)) | C7: =IF(ISNUMBER(B7),EDATE(입력값!$B$67,B7-1),"—") | D7: 시작 현금(보증금 차감 후)으로 버틸 수 있는 한계. ‘없음’이면 60개월 내 자금 부족 없음
A8: 추가 CS 인력 첫 필요 시점 | B8: =IF(MIN(월별전망!$C$49:$BJ$49)=9999,"60개월 내 없음",MIN(월별전망!$C$49:$BJ$49)) | C8: =IF(ISNUMBER(B8),EDATE(입력값!$B$67,B8-1),"—") | D8: 셀프서브 고객 대응 시간이 기존 3명의 가능 시간을 처음 넘는 달
A9: 최저 현금 잔액 | B9: =MIN(월별전망!$C$44:$BJ$44) | C9: =INDEX(월별전망!$C$5:$BJ$5,MATCH(B9,월별전망!$C$44:$BJ$44,0)) | D9: 필요한 최소 자금 = 시작 현금 − 최저 현금 잔액 (보증금 포함)
A10: 필요 최소 자금 | B10: =MAX(0,입력값!$B$72-B9)
A11: 첫 흑자 월의 고객사 수 / seat 수 | B11: =IF(ISNUMBER(B5),INDEX(월별전망!$C$10:$BJ$10,B5)+INDEX(월별전망!$C$11:$BJ$11,B5),"—") | C11: =IF(ISNUMBER(B5),INDEX(월별전망!$C$17:$BJ$17,B5),"—") | D11: 고객사 수(B, Enterprise 포함) · 총 seat(C)
A12: 최대 CS 가동률 | B12: =MAX(월별전망!$C$21:$BJ$21) | D12: 100%를 넘으면 그만큼 추가 인력이 필요했다는 뜻
A14: 연차 | B14: 매출 (원) | C14: 순이익 (원) | D14: 순이익률
A15: =연도별요약!B4 | B15: =연도별요약!B11 | C15: =연도별요약!B22 | D15: =연도별요약!B23
A16: =연도별요약!C4 | B16: =연도별요약!C11 | C16: =연도별요약!C22 | D16: =연도별요약!C23
A17: =연도별요약!D4 | B17: =연도별요약!D11 | C17: =연도별요약!D22 | D17: =연도별요약!D23
A18: =연도별요약!E4 | B18: =연도별요약!E11 | C18: =연도별요약!E22 | D18: =연도별요약!E23
A19: =연도별요약!F4 | B19: =연도별요약!F11 | C19: =연도별요약!F22 | D19: =연도별요약!F23

Sheet 입력값
A1: 입력값 — 노란 칸(파란 글씨)만 수정하세요
A2: 모든 금액은 원(KRW) 기준. 예시값은 가정이며, 실제 값으로 바꿔 넣어야 합니다.
A4: 1. Scalyo 요금제 (seat당 월 요금) — 출처: app-v2/frontend/functions/api/_config/prices.js, src/config/plans.config.js
A5: 플랜 | B5: KRW / seat | C5: EUR / seat | D5: USD / seat | E5: 최대 seat | F5: 적용 단가 (원/seat) | G5: 비고
A6: Starter | B6: 139000 | C6: 79 | D6: 89 | E6: 3 | F6: =IF(입력값!$B$12="EUR",C6*입력값!$B$13,IF(입력값!$B$12="USD",D6*입력값!$B$14,B6)) | G6: 코드 기준 가격. 최대 고객사 50개, seat 3개
A7: Growth | B7: 209000 | C7: 119 | D7: 139 | E7: 7 | F7: =IF(입력값!$B$12="EUR",C7*입력값!$B$13,IF(입력값!$B$12="USD",D7*입력값!$B$14,B7)) | G7: 코드 기준 가격. 고객사 무제한, seat 7개
A8: Elite | B8: 279000 | C8: 159 | D8: 189 | E8: 24 | F8: =IF(입력값!$B$12="EUR",C8*입력값!$B$13,IF(입력값!$B$12="USD",D8*입력값!$B$14,B8)) | G8: 코드 기준 가격. 고객사 무제한, seat 24개
A9: Enterprise | B9: 279000 | C9: 159 | D9: 189 | E9: 무제한 | F9: =IF(입력값!$B$12="EUR",C9*입력값!$B$13,IF(입력값!$B$12="USD",D9*입력값!$B$14,B9)) | G9: 코드에 가격 없음(별도 협의). Elite 가격을 임시 가정 — 실제 계약 단가로 수정
A11: 2. 매출 조건
A12: 청구 통화 | B12: KRW | G12: KRW / EUR / USD 중 선택. 해외 고객이 EUR·USD로 결제하면 환율로 원화 환산
A13: 환율: 1 EUR = ? 원 | B13: 1600 | G13: 가정값 — 최신 환율로 수정
A14: 환율: 1 USD = ? 원 | B14: 1400 | G14: 가정값 — 최신 환율로 수정
A15: 요금에 부가세 포함 여부 | B15: 별도 | G15: ‘별도’: 표시 가격 전액이 매출(B2B 관행). ‘포함’: 가격 ÷ (1+부가세율)만 매출
A16: 부가세율 | B16: 0.1 | G16: 대한민국 부가가치세 10%
A17: 결제 수수료율 (Stripe 등) | B17: 0.035 | G17: 가정값 — 해외카드·환전 수수료 포함 추정. 실제 정산 내역으로 수정
A18: 매출 인식 비율 (부가세 반영) | B18: =IF(입력값!$B$15="포함",1/(1+입력값!$B$16),1) | G18: 계산값: 표시 가격 중 회사 매출로 잡히는 비율
A20: 3. 변동비 — seat당 월 비용 (플랜이 높을수록 AI 사용량 증가)
A21: 항목 | B21: Starter | C21: Growth | D21: Elite | E21: Enterprise | G21: 비고
A22: AI 비용 (Mistral 등, seat당 월) | B22: 3000 | C22: 6000 | D22: 15000 | E22: 20000 | G22: 가정값 — Elite부터 AI 이메일 스튜디오·자동 플레이북으로 AI 호출이 크게 늘어남. 실제 청구서로 수정
A23: 기타 변동비 (DB·이메일·스토리지, seat당 월) | B23: 2000 | C23: 2000 | D23: 2000 | E23: 2000 | G23: 가정값 — Supabase·Resend·스토리지 사용량을 seat 수로 나눈 추정
A24: → seat당 월 변동비 합계 | B24: =B22+B23 | C24: =C22+C23 | D24: =D22+D23 | E24: =E22+E23
A26: 4. 월 고정비 (인건비 제외)
A27: 월세 (관리비 포함) | B27: 1500000 | G27: 가정값 — 실제 계약서 금액으로 수정
A28: 인프라·SaaS 도구 고정비 | B28: 500000 | G28: 가정값 — Cloudflare, Supabase 기본 요금, 도메인, 협업툴 등
A29: 마케팅·영업비 | B29: 2000000 | G29: 가정값
A30: 기타 (세무기장·보험·통신 등) | B30: 700000 | G30: 가정값
A31: 인건비 제외 고정비 합계 (월) | B31: =SUM(B27:B30)
A33: 4-1. 초기 비용 (1회)
A34: 사무실 보증금 | B34: 15000000 | G34: 1개월차에 현금에서만 빠짐. 돌려받는 돈이라 비용(손익)이 아님. 60개월 안에 반환되지 않는다고 가정
A35: 기타 초기 비용 (집기·PC·법인 설립 등) | B35: 0 | G35: 1개월차 비용으로 한 번에 처리(감가상각 생략). 없으면 0
A37: 5. 인건비 — 직원 3명
A38: 직원 | B38: 연봉 (원) | G38: 비고
A39: 직원 1 | B39: 50000000 | G39: 가정값 — 세전 연봉(비과세 포함 총액)
A40: 직원 2 | B40: 50000000 | G40: 가정값 — 세전 연봉(비과세 포함 총액)
A41: 직원 3 | B41: 50000000 | G41: 가정값 — 세전 연봉(비과세 포함 총액)
A42: 연봉 합계 | B42: =SUM(B39:B41)
A43: 국민연금 (사업주 부담) | B43: 0.0475 | G43: 2026년 요율 9.5%의 절반 — 확인 필요
A44: 건강보험 (사업주 부담) | B44: 0.03595 | G44: 2026년 요율 7.19%의 절반 — 확인 필요
A45: 장기요양보험 (건강보험료 대비) | B45: 0.1314 | G45: 건강보험료 × 이 비율. 2026년 추정 — 확인 필요
A46: 고용보험 (사업주 부담) | B46: 0.0115 | G46: 실업급여 0.9% + 고용안정·직업능력 0.25% (150인 미만)
...

Sheet 손익분기계산기
A1: 손익분기 계산기 — 평균 고객사 수와 seat 수를 넣으면 월 순이익이 나옵니다
A2: 노란 칸에 플랜별 ‘평균 고객사 수’와 ‘고객사당 평균 seat’를 입력. 세금은 이 월 손익이 1년 내내 유지된다고 보고 연 환산(이월결손금 미반영). 온보딩·구축비 같은 1회성 비용은 제외.
A4: 1. 입력: 고객사 수와 seat 수
A5: 플랜 | B5: 평균 고객사 수 | C5: 고객사당 평균 seat | D5: 총 seat | E5: 적용 단가 (원/seat) | F5: 월 매출 (원) | G5: 월 공헌이익 (원) | H5: 월 대응 시간
A6: Starter | B6: 10 | C6: 2.5 | D6: =B6*C6 | E6: =입력값!$F$6 | F6: =D6*E6*입력값!$B$18 | G6: =F6*(1-입력값!$B$17)-D6*입력값!$B$24 | H6: =B6*입력값!$B$90+D6*입력값!$B$89 | I6: =IF(AND(ISNUMBER(입력값!$E$6),C6>입력값!$E$6),"⚠ 최대 seat 초과","")
A7: Growth | B7: 8 | C7: 5 | D7: =B7*C7 | E7: =입력값!$F$7 | F7: =D7*E7*입력값!$B$18 | G7: =F7*(1-입력값!$B$17)-D7*입력값!$C$24 | H7: =B7*입력값!$C$90+D7*입력값!$C$89 | I7: =IF(AND(ISNUMBER(입력값!$E$7),C7>입력값!$E$7),"⚠ 최대 seat 초과","")
A8: Elite | B8: 3 | C8: 12 | D8: =B8*C8 | E8: =입력값!$F$8 | F8: =D8*E8*입력값!$B$18 | G8: =F8*(1-입력값!$B$17)-D8*입력값!$D$24 | H8: =B8*입력값!$D$90+D8*입력값!$D$89 | I8: =IF(AND(ISNUMBER(입력값!$E$8),C8>입력값!$E$8),"⚠ 최대 seat 초과","")
A9: Enterprise | B9: 0 | C9: 50 | D9: =B9*C9 | E9: =입력값!$F$9 | F9: =D9*E9*입력값!$B$18 | G9: =F9*(1-입력값!$B$17)-D9*입력값!$E$24 | H9: 전담 CSM | I9: =IF(AND(ISNUMBER(입력값!$E$9),C9>입력값!$E$9),"⚠ 최대 seat 초과","")
A10: 합계 | B10: =SUM(B6:B9) | C10: =IF(B10>0,D10/B10,0) | D10: =SUM(D6:D9) | F10: =SUM(F6:F9) | G10: =SUM(G6:G9) | H10: =SUM(H6:H9)
C11: ↑ 고객사당 평균 seat
A13: 2. 고객 대응 인력 (셀프서브 플랜)
A14: 필요 대응 시간 (월) | B14: =H10
A15: → 기존 인력 CS 가능 시간 (월) | B15: =입력값!$B$96
A16: CS 가동률 (필요 ÷ 가능) | B16: =IF(손익분기계산기!$B$15>0,손익분기계산기!$B$14/손익분기계산기!$B$15,0)
A17: 추가 CS 인력 (명) | B17: =IF(입력값!$B$99="비례",MAX(0,손익분기계산기!$B$14-손익분기계산기!$B$15)/입력값!$B$98,ROUNDUP(MAX(0,손익분기계산기!$B$14-손익분기계산기!$B$15)/입력값!$B$98,0))
A18: 추가 CS 인력 월 비용 | B18: =손익분기계산기!$B$17*입력값!$B$100
A19: 현재 인력으로 감당 가능한 최대 고객사 수 | B19: =IF(H10>0,손익분기계산기!$B$15/(H10/SUM(B6:B8)),"—") | G19: 현재 플랜 구성 기준. 넘으면 추가 채용 필요
A21: 3. Enterprise (서버 구축 + 전담 CSM)
A22: Enterprise 고객사 수 | B22: =B9
A23: 전담 CSM (명) | B23: =B9*입력값!$B$109
A24: 전담 CSM 월 비용 | B24: =손익분기계산기!$B$23*입력값!$B$110
A25: 서버 유지보수 월 비용 | B25: =B9*입력값!$B$107
A26: Enterprise 고객사 1곳 기준 (C9 seat 수 사용)
A27: 1곳당 월 공헌이익 | B27: =C9*E9*입력값!$B$18*(1-입력값!$B$17)-C9*입력값!$E$24
A28: 1곳당 월 전담 비용 (CSM + 유지보수) | B28: =입력값!$B$109*입력값!$B$110+입력값!$B$107
A29: → 1곳당 월 이익 | B29: =손익분기계산기!$B$27-손익분기계산기!$B$28
A30: 구축비 회수 기간 (개월) | B30: =IF(입력값!$B$105-입력값!$B$106<=0,0,IF(손익분기계산기!$B$29>0,(입력값!$B$105-입력값!$B$106)/손익분기계산기!$B$29,"회수 불가")) | G30: (구축비 − 구축비 청구액) ÷ 1곳당 월 이익
A31: 1곳이 적자가 안 나려면 필요한 최소 seat | B31: =IF(E9*입력값!$B$18*(1-입력값!$B$17)-입력값!$E$24>0,손익분기계산기!$B$28/(E9*입력값!$B$18*(1-입력값!$B$17)-입력값!$E$24),"—") | G31: 전담 CSM + 유지보수 비용을 seat 매출로 메우는 지점
A33: 4. 월 손익 (원)
A34: 매출 | B34: =F10
A35: (−) 결제 수수료 | B35: =-F10*입력값!$B$17
A36: (−) seat 변동비 (AI 포함) | B36: =-(D6*입력값!$B$24+D7*입력값!$C$24+D8*입력값!$D$24+D9*입력값!$E$24)
A37: → 공헌이익 | B37: =G10
A38: (−) 인건비 (직원 3명, 1년차) | B38: =-입력값!$B$51
A39: (−) 추가 CS 인력 | B39: =-손익분기계산기!$B$18
A40: (−) Enterprise 전담 CSM | B40: =-손익분기계산기!$B$24
A41: (−) Enterprise 서버 유지보수 | B41: =-손익분기계산기!$B$25
A42: (−) 월세 | B42: =-입력값!$B$27
A43: (−) 기타 고정비 | B43: =-(입력값!$B$31-입력값!$B$27)
A44: → 세전이익 (영업이익) | B44: =손익분기계산기!$B$37+SUM(B38:B43)
...

Sheet 월별전망
A1: 월별 전망 — 성장 가정(입력값 8~10번)에 따른 60개월 손익
A2: 모두 계산값. 수정은 ‘입력값’ 시트에서. 셀프서브 고객사 수는 기대값이라 소수가 나올 수 있습니다.
A4: 개월차 | C4: 1 | D4: 2 | E4: 3 | F4: 4 | G4: 5 | H4: 6 | I4: 7 | J4: 8 | K4: 9 | L4: 10 | M4: 11 | N4: 12 | O4: 13 | P4: 14 | Q4: 15 | R4: 16 | S4: 17 | T4: 18 | U4: 19 | V4: 20 | W4: 21 | X4: 22 | Y4: 23 | Z4: 24 | AA4: 25 | AB4: 26 | AC4: 27 | AD4: 28 | AE4: 29 | AF4: 30 | AG4: 31 | AH4: 32 | AI4: 33 | AJ4: 34 | AK4: 35 | AL4: 36 | AM4: 37 | AN4: 38 | AO4: 39 | AP4: 40 | AQ4: 41 | AR4: 42 | AS4: 43 | AT4: 44 | AU4: 45 | AV4: 46 | AW4: 47 | AX4: 48 | AY4: 49 | AZ4: 50 | BA4: 51 | BB4: 52 | BC4: 53 | BD4: 54 | BE4: 55 | BF4: 56 | BG4: 57 | BH4: 58 | BI4: 59 | BJ4: 60
A5: 월 | C5: =EDATE(입력값!$B$67,C4-1) | D5: =EDATE(입력값!$B$67,D4-1) | E5: =EDATE(입력값!$B$67,E4-1) | F5: =EDATE(입력값!$B$67,F4-1) | G5: =EDATE(입력값!$B$67,G4-1) | H5: =EDATE(입력값!$B$67,H4-1) | I5: =EDATE(입력값!$B$67,I4-1) | J5: =EDATE(입력값!$B$67,J4-1) | ... BJ5: =EDATE(입력값!$B$67,BJ4-1)
A6: 연차 | C6: =INT((C4-1)/12)+1 | D6: =INT((D4-1)/12)+1 | E6: =INT((E4-1)/12)+1 | F6: =INT((F4-1)/12)+1 | G6: =INT((G4-1)/12)+1 | H6: =INT((H4-1)/12)+1 | I6: =INT((I4-1)/12)+1 | J6: =INT((J4-1)/12)+1 | ... BJ6: =INT((BJ4-1)/12)+1
A7: 고객
A8: 신규 고객사 (셀프서브) | C8: =입력값!$B$69*(1+입력값!$B$70)^(C4-1) | D8: =입력값!$B$69*(1+입력값!$B$70)^(D4-1) | E8: =입력값!$B$69*(1+입력값!$B$70)^(E4-1) | F8: =입력값!$B$69*(1+입력값!$B$70)^(F4-1) | G8: =입력값!$B$69*(1+입력값!$B$70)^(G4-1) | H8: =입력값!$B$69*(1+입력값!$B$70)^(H4-1) | I8: =입력값!$B$69*(1+입력값!$B$70)^(I4-1) | J8: =입력값!$B$69*(1+입력값!$B$70)^(J4-1) | ... BJ8: =입력값!$B$69*(1+입력값!$B$70)^(BJ4-1)
A9: 이탈 고객사 (셀프서브) | C9: =입력값!$B$68*입력값!$B$71 | D9: =C10*입력값!$B$71 | E9: =D10*입력값!$B$71 | F9: =E10*입력값!$B$71 | G9: =F10*입력값!$B$71 | H9: =G10*입력값!$B$71 | I9: =H10*입력값!$B$71 | J9: =I10*입력값!$B$71 | K9: =J10*입력값!$B$71 | ... BJ9: =BI10*입력값!$B$71
A10: 기말 고객사 수 (셀프서브) | C10: =입력값!$B$68-C9+C8 | D10: =C10-D9+D8 | E10: =D10-E9+E8 | F10: =E10-F9+F8 | G10: =F10-G9+G8 | H10: =G10-H9+H8 | I10: =H10-I9+I8 | J10: =I10-J9+J8 | K10: =J10-K9+K8 | ... BJ10: =BI10-BJ9+BJ8
A11: Enterprise 고객사 수 | C11: =COUNTIFS(입력값!$B$113:$B$117,"<="&C4,입력값!$B$113:$B$117,">0") | D11: =COUNTIFS(입력값!$B$113:$B$117,"<="&D4,입력값!$B$113:$B$117,">0") | E11: =COUNTIFS(입력값!$B$113:$B$117,"<="&E4,입력값!$B$113:$B$117,">0") | F11: =COUNTIFS(입력값!$B$113:$B$117,"<="&F4,입력값!$B$113:$B$117,">0") | G11: =COUNTIFS(입력값!$B$113:$B$117,"<="&G4,입력값!$B$113:$B$117,">0") | H11: =COUNTIFS(입력값!$B$113:$B$117,"<="&H4,입력값!$B$113:$B$117,">0") | I11: =COUNTIFS(입력값!$B$113:$B$117,"<="&I4,입력값!$B$113:$B$117,">0") | J11: =COUNTIFS(입력값!$B$113:$B$117,"<="&J4,입력값!$B$113:$B$117,">0") | ... BJ11: =COUNTIFS(입력값!$B$113:$B$117,"<="&BJ4,입력값!$B$113:$B$117,">0")
A12: Enterprise 신규 계약 | C12: =COUNTIF(입력값!$B$113:$B$117,C4) | D12: =COUNTIF(입력값!$B$113:$B$117,D4) | E12: =COUNTIF(입력값!$B$113:$B$117,E4) | F12: =COUNTIF(입력값!$B$113:$B$117,F4) | G12: =COUNTIF(입력값!$B$113:$B$117,G4) | H12: =COUNTIF(입력값!$B$113:$B$117,H4) | I12: =COUNTIF(입력값!$B$113:$B$117,I4) | J12: =COUNTIF(입력값!$B$113:$B$117,J4) | ... BJ12: =COUNTIF(입력값!$B$113:$B$117,BJ4)
A13: seat — Starter | C13: =C10*입력값!$B$75*입력값!$C$75 | D13: =D10*입력값!$B$75*입력값!$C$75 | E13: =E10*입력값!$B$75*입력값!$C$75 | F13: =F10*입력값!$B$75*입력값!$C$75 | G13: =G10*입력값!$B$75*입력값!$C$75 | H13: =H10*입력값!$B$75*입력값!$C$75 | I13: =I10*입력값!$B$75*입력값!$C$75 | J13: =J10*입력값!$B$75*입력값!$C$75 | ... BJ13: =BJ10*입력값!$B$75*입력값!$C$75
A14: seat — Growth | C14: =C10*입력값!$B$76*입력값!$C$76 | D14: =D10*입력값!$B$76*입력값!$C$76 | E14: =E10*입력값!$B$76*입력값!$C$76 | F14: =F10*입력값!$B$76*입력값!$C$76 | G14: =G10*입력값!$B$76*입력값!$C$76 | H14: =H10*입력값!$B$76*입력값!$C$76 | I14: =I10*입력값!$B$76*입력값!$C$76 | J14: =J10*입력값!$B$76*입력값!$C$76 | ... BJ14: =BJ10*입력값!$B$76*입력값!$C$76
A15: seat — Elite | C15: =C10*입력값!$B$77*입력값!$C$77 | D15: =D10*입력값!$B$77*입력값!$C$77 | E15: =E10*입력값!$B$77*입력값!$C$77 | F15: =F10*입력값!$B$77*입력값!$C$77 | G15: =G10*입력값!$B$77*입력값!$C$77 | H15: =H10*입력값!$B$77*입력값!$C$77 | I15: =I10*입력값!$B$77*입력값!$C$77 | J15: =J10*입력값!$B$77*입력값!$C$77 | ... BJ15: =BJ10*입력값!$B$77*입력값!$C$77
A16: seat — Enterprise | C16: =SUMIFS(입력값!$C$113:$C$117,입력값!$B$113:$B$117,"<="&C4,입력값!$B$113:$B$117,">0") | D16: =SUMIFS(입력값!$C$113:$C$117,입력값!$B$113:$B$117,"<="&D4,입력값!$B$113:$B$117,">0") | E16: =SUMIFS(입력값!$C$113:$C$117,입력값!$B$113:$B$117,"<="&E4,입력값!$B$113:$B$117,">0") | F16: =SUMIFS(입력값!$C$113:$C$117,입력값!$B$113:$B$117,"<="&F4,입력값!$B$113:$B$117,">0") | G16: =SUMIFS(입력값!$C$113:$C$117,입력값!$B$113:$B$117,"<="&G4,입력값!$B$113:$B$117,">0") | H16: =SUMIFS(입력값!$C$113:$C$117,입력값!$B$113:$B$117,"<="&H4,입력값!$B$113:$B$117,">0") | I16: =SUMIFS(입력값!$C$113:$C$117,입력값!$B$113:$B$117,"<="&I4,입력값!$B$113:$B$117,">0") | J16: =SUMIFS(입력값!$C$113:$C$117,입력값!$B$113:$B$117,"<="&J4,입력값!$B$113:$B$117,">0") | ... BJ16: =SUMIFS(입력값!$C$113:$C$117,입력값!$B$113:$B$117,"<="&BJ4,입력값!$B$113:$B$117,">0")
A17: 총 seat | C17: =SUM(C13:C16) | D17: =SUM(D13:D16) | E17: =SUM(E13:E16) | F17: =SUM(F13:F16) | G17: =SUM(G13:G16) | H17: =SUM(H13:H16) | I17: =SUM(I13:I16) | J17: =SUM(J13:J16) | ... BJ17: =SUM(BJ13:BJ16)
A18: 고객 대응 (CS)
A19: 필요 대응 시간 (셀프서브) | C19: =C10*입력값!$B$75*입력값!$B$90+C13*입력값!$B$89+C8*입력값!$B$75*입력값!$B$88+C10*입력값!$B$76*입력값!$C$90+C14*입력값!$C$89+C8*입력값!$B$76*입력값!$C$88+C10*입력값!$B$77*입력값!$D$90+C15*입력값!$D$89+C8*입력값!$B$77*입력값!$D$88 | D19: =D10*입력값!$B$75*입력값!$B$90+D13*입력값!$B$89+D8*입력값!$B$75*입력값!$B$88+D10*입력값!$B$76*입력값!$C$90+D14*입력값!$C$89+D8*입력값!$B$76*입력값!$C$88+D10*입력값!$B$77*입력값!$D$90+D15*입력값!$D$89+D8*입력값!$B$77*입력값!$D$88 | E19: =E10*입력값!$B$75*입력값!$B$90+E13*입력값!$B$89+E8*입력값!$B$75*입력값!$B$88+E10*입력값!$B$76*입력값!$C$90+E14*입력값!$C$89+E8*입력값!$B$76*입력값!$C$88+E10*입력값!$B$77*입력값!$D$90+E15*입력값!$D$89+E8*입력값!$B$77*입력값!$D$88 | F19: =F10*입력값!$B$75*입력값!$B$90+F13*입력값!$B$89+F8*입력값!$B$75*입력값!$B$88+F10*입력값!$B$76*입력값!$C$90+F14*입력값!$C$89+F8*입력값!$B$76*입력값!$C$88+F10*입력값!$B$77*입력값!$D$90+F15*입력값!$D$89+F8*입력값!$B$77*입력값!$D$88 | G19: =G10*입력값!$B$75*입력값!$B$90+G13*입력값!$B$89+G8*입력값!$B$75*입력값!$B$88+G10*입력값!$B$76*입력값!$C$90+G14*입력값!$C$89+G8*입력값!$B$76*입력값!$C$88+G10*입력값!$B$77*입력값!$D$90+G15*입력값!$D$89+G8*입력값!$B$77*입력값!$D$88 | H19: =H10*입력값!$B$75*입력값!$B$90+H13*입력값!$B$89+H8*입력값!$B$75*입력값!$B$88+H10*입력값!$B$76*입력값!$C$90+H14*입력값!$C$89+H8*입력값!$B$76*입력값!$C$88+H10*입력값!$B$77*입력값!$D$90+H15*입력값!$D$89+H8*입력값!$B$77*입력값!$D$88 | I19: =I10*입력값!$B$75*입력값!$B$90+I13*입력값!$B$89+I8*입력값!$B$75*입력값!$B$88+I10*입력값!$B$76*입력값!$C$90+I14*입력값!$C$89+I8*입력값!$B$76*입력값!$C$88+I10*입력값!$B$77*입력값!$D$90+I15*입력값!$D$89+I8*입력값!$B$77*입력값!$D$88 | J19: =J10*입력값!$B$75*입력값!$B$90+J13*입력값!$B$89+J8*입력값!$B$75*입력값!$B$88+J10*입력값!$B$76*입력값!$C$90+J14*입력값!$C$89+J8*입력값!$B$76*입력값!$C$88+J10*입력값!$B$77*입력값!$D$90+J15*입력값!$D$89+J8*입력값!$B$77*입력값!$D$88 | ... BJ19: =BJ10*입력값!$B$75*입력값!$B$90+BJ13*입력값!$B$89+BJ8*입력값!$B$75*입력값!$B$88+BJ10*입력값!$B$76*입력값!$C$90+BJ14*입력값!$C$89+BJ8*입력값!$B$76*입력값!$C$88+BJ10*입력값!$B$77*입력값!$D$90+BJ15*입력값!$D$89+BJ8*입력값!$B$77*입력값!$D$88
A20: 기존 인력 대응 가능 시간 | C20: =입력값!$B$96 | D20: =입력값!$B$96 | E20: =입력값!$B$96 | F20: =입력값!$B$96 | G20: =입력값!$B$96 | H20: =입력값!$B$96 | I20: =입력값!$B$96 | J20: =입력값!$B$96 | ... BJ20: =입력값!$B$96
A21: CS 가동률 | C21: =IF(C20>0,C19/C20,0) | D21: =IF(D20>0,D19/D20,0) | E21: =IF(E20>0,E19/E20,0) | F21: =IF(F20>0,F19/F20,0) | G21: =IF(G20>0,G19/G20,0) | H21: =IF(H20>0,H19/H20,0) | I21: =IF(I20>0,I19/I20,0) | J21: =IF(J20>0,J19/J20,0) | ... BJ21: =IF(BJ20>0,BJ19/BJ20,0)
A22: 추가 CS 인력 (명) | C22: =IF(입력값!$B$99="비례",MAX(0,C19-C20)/입력값!$B$98,ROUNDUP(MAX(0,C19-C20)/입력값!$B$98,0)) | D22: =IF(입력값!$B$99="비례",MAX(0,D19-D20)/입력값!$B$98,ROUNDUP(MAX(0,D19-D20)/입력값!$B$98,0)) | E22: =IF(입력값!$B$99="비례",MAX(0,E19-E20)/입력값!$B$98,ROUNDUP(MAX(0,E19-E20)/입력값!$B$98,0)) | F22: =IF(입력값!$B$99="비례",MAX(0,F19-F20)/입력값!$B$98,ROUNDUP(MAX(0,F19-F20)/입력값!$B$98,0)) | G22: =IF(입력값!$B$99="비례",MAX(0,G19-G20)/입력값!$B$98,ROUNDUP(MAX(0,G19-G20)/입력값!$B$98,0)) | H22: =IF(입력값!$B$99="비례",MAX(0,H19-H20)/입력값!$B$98,ROUNDUP(MAX(0,H19-H20)/입력값!$B$98,0)) | I22: =IF(입력값!$B$99="비례",MAX(0,I19-I20)/입력값!$B$98,ROUNDUP(MAX(0,I19-I20)/입력값!$B$98,0)) | J22: =IF(입력값!$B$99="비례",MAX(0,J19-J20)/입력값!$B$98,ROUNDUP(MAX(0,J19-J20)/입력값!$B$98,0)) | ... BJ22: =IF(입력값!$B$99="비례",MAX(0,BJ19-BJ20)/입력값!$B$98,ROUNDUP(MAX(0,BJ19-BJ20)/입력값!$B$98,0))
A23: Enterprise 전담 CSM (명) | C23: =SUMIFS(입력값!$D$113:$D$117,입력값!$B$113:$B$117,"<="&C4,입력값!$B$113:$B$117,">0") | D23: =SUMIFS(입력값!$D$113:$D$117,입력값!$B$113:$B$117,"<="&D4,입력값!$B$113:$B$117,">0") | E23: =SUMIFS(입력값!$D$113:$D$117,입력값!$B$113:$B$117,"<="&E4,입력값!$B$113:$B$117,">0") | F23: =SUMIFS(입력값!$D$113:$D$117,입력값!$B$113:$B$117,"<="&F4,입력값!$B$113:$B$117,">0") | G23: =SUMIFS(입력값!$D$113:$D$117,입력값!$B$113:$B$117,"<="&G4,입력값!$B$113:$B$117,">0") | H23: =SUMIFS(입력값!$D$113:$D$117,입력값!$B$113:$B$117,"<="&H4,입력값!$B$113:$B$117,">0") | I23: =SUMIFS(입력값!$D$113:$D$117,입력값!$B$113:$B$117,"<="&I4,입력값!$B$113:$B$117,">0") | J23: =SUMIFS(입력값!$D$113:$D$117,입력값!$B$113:$B$117,"<="&J4,입력값!$B$113:$B$117,">0") | ... BJ23: =SUMIFS(입력값!$D$113:$D$117,입력값!$B$113:$B$117,"<="&BJ4,입력값!$B$113:$B$117,">0")
A24: 손익 (원)
A25: 매출 | C25: =(C13*입력값!$F$6+C14*입력값!$F$7+C15*입력값!$F$8+C16*입력값!$F$9)*입력값!$B$18 | D25: =(D13*입력값!$F$6+D14*입력값!$F$7+D15*입력값!$F$8+D16*입력값!$F$9)*입력값!$B$18 | E25: =(E13*입력값!$F$6+E14*입력값!$F$7+E15*입력값!$F$8+E16*입력값!$F$9)*입력값!$B$18 | F25: =(F13*입력값!$F$6+F14*입력값!$F$7+F15*입력값!$F$8+F16*입력값!$F$9)*입력값!$B$18 | G25: =(G13*입력값!$F$6+G14*입력값!$F$7+G15*입력값!$F$8+G16*입력값!$F$9)*입력값!$B$18 | H25: =(H13*입력값!$F$6+H14*입력값!$F$7+H15*입력값!$F$8+H16*입력값!$F$9)*입력값!$B$18 | I25: =(I13*입력값!$F$6+I14*입력값!$F$7+I15*입력값!$F$8+I16*입력값!$F$9)*입력값!$B$18 | J25: =(J13*입력값!$F$6+J14*입력값!$F$7+J15*입력값!$F$8+J16*입력값!$F$9)*입력값!$B$18 | ... BJ25: =(BJ13*입력값!$F$6+BJ14*입력값!$F$7+BJ15*입력값!$F$8+BJ16*입력값!$F$9)*입력값!$B$18
A26: 구축비 청구 수입 (Enterprise) | C26: =C12*입력값!$B$106 | D26: =D12*입력값!$B$106 | E26: =E12*입력값!$B$106 | F26: =F12*입력값!$B$106 | G26: =G12*입력값!$B$106 | H26: =H12*입력값!$B$106 | I26: =I12*입력값!$B$106 | J26: =J12*입력값!$B$106 | ... BJ26: =BJ12*입력값!$B$106
A27: (−) 결제 수수료 | C27: =-C25*입력값!$B$17 | D27: =-D25*입력값!$B$17 | E27: =-E25*입력값!$B$17 | F27: =-F25*입력값!$B$17 | G27: =-G25*입력값!$B$17 | H27: =-H25*입력값!$B$17 | I27: =-I25*입력값!$B$17 | J27: =-J25*입력값!$B$17 | ... BJ27: =-BJ25*입력값!$B$17
A28: (−) seat 변동비 (AI 포함) | C28: =-(C13*입력값!$B$24+C14*입력값!$C$24+C15*입력값!$D$24+C16*입력값!$E$24) | D28: =-(D13*입력값!$B$24+D14*입력값!$C$24+D15*입력값!$D$24+D16*입력값!$E$24) | E28: =-(E13*입력값!$B$24+E14*입력값!$C$24+E15*입력값!$D$24+E16*입력값!$E$24) | F28: =-(F13*입력값!$B$24+F14*입력값!$C$24+F15*입력값!$D$24+F16*입력값!$E$24) | G28: =-(G13*입력값!$B$24+G14*입력값!$C$24+G15*입력값!$D$24+G16*입력값!$E$24) | H28: =-(H13*입력값!$B$24+H14*입력값!$C$24+H15*입력값!$D$24+H16*입력값!$E$24) | I28: =-(I13*입력값!$B$24+I14*입력값!$C$24+I15*입력값!$D$24+I16*입력값!$E$24) | J28: =-(J13*입력값!$B$24+J14*입력값!$C$24+J15*입력값!$D$24+J16*입력값!$E$24) | ... BJ28: =-(BJ13*입력값!$B$24+BJ14*입력값!$C$24+BJ15*입력값!$D$24+BJ16*입력값!$E$24)
A29: → 공헌이익 | C29: =C25+C26+C27+C28 | D29: =D25+D26+D27+D28 | E29: =E25+E26+E27+E28 | F29: =F25+F26+F27+F28 | G29: =G25+G26+G27+G28 | H29: =H25+H26+H27+H28 | I29: =I25+I26+I27+I28 | J29: =J25+J26+J27+J28 | ... BJ29: =BJ25+BJ26+BJ27+BJ28
A30: (−) 인건비 (3명) | C30: =-입력값!$B$51*(1+입력값!$B$49)^(C6-1) | D30: =-입력값!$B$51*(1+입력값!$B$49)^(D6-1) | E30: =-입력값!$B$51*(1+입력값!$B$49)^(E6-1) | F30: =-입력값!$B$51*(1+입력값!$B$49)^(F6-1) | G30: =-입력값!$B$51*(1+입력값!$B$49)^(G6-1) | H30: =-입력값!$B$51*(1+입력값!$B$49)^(H6-1) | I30: =-입력값!$B$51*(1+입력값!$B$49)^(I6-1) | J30: =-입력값!$B$51*(1+입력값!$B$49)^(J6-1) | ... BJ30: =-입력값!$B$51*(1+입력값!$B$49)^(BJ6-1)
A31: (−) 추가 CS 인력 | C31: =-C22*입력값!$B$100*(1+입력값!$B$49)^(C6-1) | D31: =-D22*입력값!$B$100*(1+입력값!$B$49)^(D6-1) | E31: =-E22*입력값!$B$100*(1+입력값!$B$49)^(E6-1) | F31: =-F22*입력값!$B$100*(1+입력값!$B$49)^(F6-1) | G31: =-G22*입력값!$B$100*(1+입력값!$B$49)^(G6-1) | H31: =-H22*입력값!$B$100*(1+입력값!$B$49)^(H6-1) | I31: =-I22*입력값!$B$100*(1+입력값!$B$49)^(I6-1) | J31: =-J22*입력값!$B$100*(1+입력값!$B$49)^(J6-1) | ... BJ31: =-BJ22*입력값!$B$100*(1+입력값!$B$49)^(BJ6-1)
A32: (−) Enterprise 전담 CSM | C32: =-C23*입력값!$B$110*(1+입력값!$B$49)^(C6-1) | D32: =-D23*입력값!$B$110*(1+입력값!$B$49)^(D6-1) | E32: =-E23*입력값!$B$110*(1+입력값!$B$49)^(E6-1) | F32: =-F23*입력값!$B$110*(1+입력값!$B$49)^(F6-1) | G32: =-G23*입력값!$B$110*(1+입력값!$B$49)^(G6-1) | H32: =-H23*입력값!$B$110*(1+입력값!$B$49)^(H6-1) | I32: =-I23*입력값!$B$110*(1+입력값!$B$49)^(I6-1) | J32: =-J23*입력값!$B$110*(1+입력값!$B$49)^(J6-1) | ... BJ32: =-BJ23*입력값!$B$110*(1+입력값!$B$49)^(BJ6-1)
A33: (−) Enterprise 서버 유지보수 | C33: =-C11*입력값!$B$107 | D33: =-D11*입력값!$B$107 | E33: =-E11*입력값!$B$107 | F33: =-F11*입력값!$B$107 | G33: =-G11*입력값!$B$107 | H33: =-H11*입력값!$B$107 | I33: =-I11*입력값!$B$107 | J33: =-J11*입력값!$B$107 | ... BJ33: =-BJ11*입력값!$B$107
A34: (−) Enterprise 서버 구축비 (1회) | C34: =-C12*입력값!$B$105 | D34: =-D12*입력값!$B$105 | E34: =-E12*입력값!$B$105 | F34: =-F12*입력값!$B$105 | G34: =-G12*입력값!$B$105 | H34: =-H12*입력값!$B$105 | I34: =-I12*입력값!$B$105 | J34: =-J12*입력값!$B$105 | ... BJ34: =-BJ12*입력값!$B$105
A35: (−) 기타 초기 비용 (1회) | C35: =IF(C4=1,-입력값!$B$35,0) | D35: =IF(D4=1,-입력값!$B$35,0) | E35: =IF(E4=1,-입력값!$B$35,0) | F35: =IF(F4=1,-입력값!$B$35,0) | G35: =IF(G4=1,-입력값!$B$35,0) | H35: =IF(H4=1,-입력값!$B$35,0) | I35: =IF(I4=1,-입력값!$B$35,0) | J35: =IF(J4=1,-입력값!$B$35,0) | ... BJ35: =IF(BJ4=1,-입력값!$B$35,0)
A36: (−) 월세 | C36: =-입력값!$B$27 | D36: =-입력값!$B$27 | E36: =-입력값!$B$27 | F36: =-입력값!$B$27 | G36: =-입력값!$B$27 | H36: =-입력값!$B$27 | I36: =-입력값!$B$27 | J36: =-입력값!$B$27 | ... BJ36: =-입력값!$B$27
A37: (−) 기타 고정비 | C37: =-(입력값!$B$31-입력값!$B$27) | D37: =-(입력값!$B$31-입력값!$B$27) | E37: =-(입력값!$B$31-입력값!$B$27) | F37: =-(입력값!$B$31-입력값!$B$27) | G37: =-(입력값!$B$31-입력값!$B$27) | H37: =-(입력값!$B$31-입력값!$B$27) | I37: =-(입력값!$B$31-입력값!$B$27) | J37: =-(입력값!$B$31-입력값!$B$27) | ... BJ37: =-(입력값!$B$31-입력값!$B$27)
A38: → 세전이익 (영업이익) | C38: =SUM(C29:C37) | D38: =SUM(D29:D37) | E38: =SUM(E29:E37) | F38: =SUM(F29:F37) | G38: =SUM(G29:G37) | H38: =SUM(H29:H37) | I38: =SUM(I29:I37) | J38: =SUM(J29:J37) | ... BJ38: =SUM(BJ29:BJ37)
A39: (−) 법인세 + 지방소득세 (연간 세액 배분) | C39: =-IF(INDEX(연도별요약!$B$24:$F$24,C6)>0,INDEX(연도별요약!$B$18:$F$18,C6)*IF(C38>0,C38/INDEX(연도별요약!$B$24:$F$24,C6),0),0) | D39: =-IF(INDEX(연도별요약!$B$24:$F$24,D6)>0,INDEX(연도별요약!$B$18:$F$18,D6)*IF(D38>0,D38/INDEX(연도별요약!$B$24:$F$24,D6),0),0) | E39: =-IF(INDEX(연도별요약!$B$24:$F$24,E6)>0,INDEX(연도별요약!$B$18:$F$18,E6)*IF(E38>0,E38/INDEX(연도별요약!$B$24:$F$24,E6),0),0) | F39: =-IF(INDEX(연도별요약!$B$24:$F$24,F6)>0,INDEX(연도별요약!$B$18:$F$18,F6)*IF(F38>0,F38/INDEX(연도별요약!$B$24:$F$24,F6),0),0) | G39: =-IF(INDEX(연도별요약!$B$24:$F$24,G6)>0,INDEX(연도별요약!$B$18:$F$18,G6)*IF(G38>0,G38/INDEX(연도별요약!$B$24:$F$24,G6),0),0) | H39: =-IF(INDEX(연도별요약!$B$24:$F$24,H6)>0,INDEX(연도별요약!$B$18:$F$18,H6)*IF(H38>0,H38/INDEX(연도별요약!$B$24:$F$24,H6),0),0) | I39: =-IF(INDEX(연도별요약!$B$24:$F$24,I6)>0,INDEX(연도별요약!$B$18:$F$18,I6)*IF(I38>0,I38/INDEX(연도별요약!$B$24:$F$24,I6),0),0) | J39: =-IF(INDEX(연도별요약!$B$24:$F$24,J6)>0,INDEX(연도별요약!$B$18:$F$18,J6)*IF(J38>0,J38/INDEX(연도별요약!$B$24:$F$24,J6),0),0) | ... BJ39: =-IF(INDEX(연도별요약!$B$24:$F$24,BJ6)>0,INDEX(연도별요약!$B$18:$F$18,BJ6)*IF(BJ38>0,BJ38/INDEX(연도별요약!$B$24:$F$24,BJ6),0),0)
A40: (−) 투자자 지분 6% (연간 배분) | C40: =-IF(INDEX(연도별요약!$B$24:$F$24,C6)>0,INDEX(연도별요약!$B$21:$F$21,C6)*IF(C38>0,C38/INDEX(연도별요약!$B$24:$F$24,C6),0),0) | D40: =-IF(INDEX(연도별요약!$B$24:$F$24,D6)>0,INDEX(연도별요약!$B$21:$F$21,D6)*IF(D38>0,D38/INDEX(연도별요약!$B$24:$F$24,D6),0),0) | E40: =-IF(INDEX(연도별요약!$B$24:$F$24,E6)>0,INDEX(연도별요약!$B$21:$F$21,E6)*IF(E38>0,E38/INDEX(연도별요약!$B$24:$F$24,E6),0),0) | F40: =-IF(INDEX(연도별요약!$B$24:$F$24,F6)>0,INDEX(연도별요약!$B$21:$F$21,F6)*IF(F38>0,F38/INDEX(연도별요약!$B$24:$F$24,F6),0),0) | G40: =-IF(INDEX(연도별요약!$B$24:$F$24,G6)>0,INDEX(연도별요약!$B$21:$F$21,G6)*IF(G38>0,G38/INDEX(연도별요약!$B$24:$F$24,G6),0),0) | H40: =-IF(INDEX(연도별요약!$B$24:$F$24,H6)>0,INDEX(연도별요약!$B$21:$F$21,H6)*IF(H38>0,H38/INDEX(연도별요약!$B$24:$F$24,H6),0),0) | I40: =-IF(INDEX(연도별요약!$B$24:$F$24,I6)>0,INDEX(연도별요약!$B$21:$F$21,I6)*IF(I38>0,I38/INDEX(연도별요약!$B$24:$F$24,I6),0),0) | J40: =-IF(INDEX(연도별요약!$B$24:$F$24,J6)>0,INDEX(연도별요약!$B$21:$F$21,J6)*IF(J38>0,J38/INDEX(연도별요약!$B$24:$F$24,J6),0),0) | ... BJ40: =-IF(INDEX(연도별요약!$B$24:$F$24,BJ6)>0,INDEX(연도별요약!$B$21:$F$21,BJ6)*IF(BJ38>0,BJ38/INDEX(연도별요약!$B$24:$F$24,BJ6),0),0)
A41: → 순이익 | C41: =C38+C39+C40 | D41: =D38+D39+D40 | E41: =E38+E39+E40 | F41: =F38+F39+F40 | G41: =G38+G39+G40 | H41: =H38+H39+H40 | I41: =I38+I39+I40 | J41: =J38+J39+J40 | ... BJ41: =BJ38+BJ39+BJ40
...

Sheet 연도별요약
A1: 연도별 요약 — 세금·투자자 몫은 연 단위로 계산
A2: 연차 = 시작 월부터 12개월 단위(회계연도 단순화). 법인세는 연간 과세표준에 누진세율, 이월결손금 공제 반영.
A4: 연차 | B4: 1 | C4: 2 | D4: 3 | E4: 4 | F4: 5
A5: 시작 월 | B5: =EDATE(입력값!$B$67,12*(B4-1)) | C5: =EDATE(입력값!$B$67,12*(C4-1)) | D5: =EDATE(입력값!$B$67,12*(D4-1)) | E5: =EDATE(입력값!$B$67,12*(E4-1)) | F5: =EDATE(입력값!$B$67,12*(F4-1))
A6: 기말 셀프서브 고객사 수 | B6: =INDEX(월별전망!$C$10:$BJ$10,12*B4) | C6: =INDEX(월별전망!$C$10:$BJ$10,12*C4) | D6: =INDEX(월별전망!$C$10:$BJ$10,12*D4) | E6: =INDEX(월별전망!$C$10:$BJ$10,12*E4) | F6: =INDEX(월별전망!$C$10:$BJ$10,12*F4)
A7: 기말 Enterprise 고객사 수 | B7: =INDEX(월별전망!$C$11:$BJ$11,12*B4) | C7: =INDEX(월별전망!$C$11:$BJ$11,12*C4) | D7: =INDEX(월별전망!$C$11:$BJ$11,12*D4) | E7: =INDEX(월별전망!$C$11:$BJ$11,12*E4) | F7: =INDEX(월별전망!$C$11:$BJ$11,12*F4)
A8: 기말 총 seat | B8: =INDEX(월별전망!$C$17:$BJ$17,12*B4) | C8: =INDEX(월별전망!$C$17:$BJ$17,12*C4) | D8: =INDEX(월별전망!$C$17:$BJ$17,12*D4) | E8: =INDEX(월별전망!$C$17:$BJ$17,12*E4) | F8: =INDEX(월별전망!$C$17:$BJ$17,12*F4)
A9: 기말 추가 CS 인력 (명) | B9: =INDEX(월별전망!$C$22:$BJ$22,12*B4) | C9: =INDEX(월별전망!$C$22:$BJ$22,12*C4) | D9: =INDEX(월별전망!$C$22:$BJ$22,12*D4) | E9: =INDEX(월별전망!$C$22:$BJ$22,12*E4) | F9: =INDEX(월별전망!$C$22:$BJ$22,12*F4)
A10: 기말 전담 CSM (명) | B10: =INDEX(월별전망!$C$23:$BJ$23,12*B4) | C10: =INDEX(월별전망!$C$23:$BJ$23,12*C4) | D10: =INDEX(월별전망!$C$23:$BJ$23,12*D4) | E10: =INDEX(월별전망!$C$23:$BJ$23,12*E4) | F10: =INDEX(월별전망!$C$23:$BJ$23,12*F4)
A11: 매출 (구축비 청구 포함) | B11: =SUMIF(월별전망!$C$6:$BJ$6,B4,월별전망!$C$25:$BJ$25)+SUMIF(월별전망!$C$6:$BJ$6,B4,월별전망!$C$26:$BJ$26) | C11: =SUMIF(월별전망!$C$6:$BJ$6,C4,월별전망!$C$25:$BJ$25)+SUMIF(월별전망!$C$6:$BJ$6,C4,월별전망!$C$26:$BJ$26) | D11: =SUMIF(월별전망!$C$6:$BJ$6,D4,월별전망!$C$25:$BJ$25)+SUMIF(월별전망!$C$6:$BJ$6,D4,월별전망!$C$26:$BJ$26) | E11: =SUMIF(월별전망!$C$6:$BJ$6,E4,월별전망!$C$25:$BJ$25)+SUMIF(월별전망!$C$6:$BJ$6,E4,월별전망!$C$26:$BJ$26) | F11: =SUMIF(월별전망!$C$6:$BJ$6,F4,월별전망!$C$25:$BJ$25)+SUMIF(월별전망!$C$6:$BJ$6,F4,월별전망!$C$26:$BJ$26)
A12: 공헌이익 | B12: =SUMIF(월별전망!$C$6:$BJ$6,B4,월별전망!$C$29:$BJ$29) | C12: =SUMIF(월별전망!$C$6:$BJ$6,C4,월별전망!$C$29:$BJ$29) | D12: =SUMIF(월별전망!$C$6:$BJ$6,D4,월별전망!$C$29:$BJ$29) | E12: =SUMIF(월별전망!$C$6:$BJ$6,E4,월별전망!$C$29:$BJ$29) | F12: =SUMIF(월별전망!$C$6:$BJ$6,F4,월별전망!$C$29:$BJ$29)
A13: (−) 고정비·인력·구축비 합계 | B13: =B14-B12 | C13: =C14-C12 | D13: =D14-D12 | E13: =E14-E12 | F13: =F14-F12
A14: → 세전이익 (영업이익) | B14: =SUMIF(월별전망!$C$6:$BJ$6,B4,월별전망!$C$38:$BJ$38) | C14: =SUMIF(월별전망!$C$6:$BJ$6,C4,월별전망!$C$38:$BJ$38) | D14: =SUMIF(월별전망!$C$6:$BJ$6,D4,월별전망!$C$38:$BJ$38) | E14: =SUMIF(월별전망!$C$6:$BJ$6,E4,월별전망!$C$38:$BJ$38) | F14: =SUMIF(월별전망!$C$6:$BJ$6,F4,월별전망!$C$38:$BJ$38)
A15: 기초 이월결손금 | B15: 0 | C15: =B19 | D15: =C19 | E15: =D19 | F15: =E19
A16: 이월결손금 공제액 | B16: =MIN(B15,MAX(0,B14)*입력값!$B$61) | C16: =MIN(C15,MAX(0,C14)*입력값!$B$61) | D16: =MIN(D15,MAX(0,D14)*입력값!$B$61) | E16: =MIN(E15,MAX(0,E14)*입력값!$B$61) | F16: =MIN(F15,MAX(0,F14)*입력값!$B$61)
A17: 과세표준 | B17: =MAX(0,B14-B16) | C17: =MAX(0,C14-C16) | D17: =MAX(0,D14-D16) | E17: =MAX(0,E14-E16) | F17: =MAX(0,F14-F16)
A18: 법인세 + 지방소득세 (감면 반영) | B18: =(MIN(B17,입력값!$A$55)*입력값!$B$55+MAX(0,MIN(B17,입력값!$A$56)-입력값!$A$55)*입력값!$B$56+MAX(0,MIN(B17,입력값!$A$57)-입력값!$A$56)*입력값!$B$57+MAX(0,B17-입력값!$A$57)*입력값!$B$58)*(1+입력값!$B$59)*(1-입력값!$B$60) | C18: =(MIN(C17,입력값!$A$55)*입력값!$B$55+MAX(0,MIN(C17,입력값!$A$56)-입력값!$A$55)*입력값!$B$56+MAX(0,MIN(C17,입력값!$A$57)-입력값!$A$56)*입력값!$B$57+MAX(0,C17-입력값!$A$57)*입력값!$B$58)*(1+입력값!$B$59)*(1-입력값!$B$60) | D18: =(MIN(D17,입력값!$A$55)*입력값!$B$55+MAX(0,MIN(D17,입력값!$A$56)-입력값!$A$55)*입력값!$B$56+MAX(0,MIN(D17,입력값!$A$57)-입력값!$A$56)*입력값!$B$57+MAX(0,D17-입력값!$A$57)*입력값!$B$58)*(1+입력값!$B$59)*(1-입력값!$B$60) | E18: =(MIN(E17,입력값!$A$55)*입력값!$B$55+MAX(0,MIN(E17,입력값!$A$56)-입력값!$A$55)*입력값!$B$56+MAX(0,MIN(E17,입력값!$A$57)-입력값!$A$56)*입력값!$B$57+MAX(0,E17-입력값!$A$57)*입력값!$B$58)*(1+입력값!$B$59)*(1-입력값!$B$60) | F18: =(MIN(F17,입력값!$A$55)*입력값!$B$55+MAX(0,MIN(F17,입력값!$A$56)-입력값!$A$55)*입력값!$B$56+MAX(0,MIN(F17,입력값!$A$57)-입력값!$A$56)*입력값!$B$57+MAX(0,F17-입력값!$A$57)*입력값!$B$58)*(1+입력값!$B$59)*(1-입력값!$B$60)
A19: 기말 이월결손금 | B19: =B15-B16+MAX(0,-B14) | C19: =C15-C16+MAX(0,-C14) | D19: =D15-D16+MAX(0,-D14) | E19: =E15-E16+MAX(0,-E14) | F19: =F15-F16+MAX(0,-F14)
A20: → 세후이익 | B20: =B14-B18 | C20: =C14-C18 | D20: =D14-D18 | E20: =E14-E18 | F20: =F14-F18
A21: (−) 투자자 지분 6% | B21: =MAX(0,B20)*입력값!$B$64 | C21: =MAX(0,C20)*입력값!$B$64 | D21: =MAX(0,D20)*입력값!$B$64 | E21: =MAX(0,E20)*입력값!$B$64 | F21: =MAX(0,F20)*입력값!$B$64
A22: → 순이익 | B22: =B20-B21 | C22: =C20-C21 | D22: =D20-D21 | E22: =E20-E21 | F22: =F20-F21
A23: 순이익률 | B23: =IF(B11>0,B22/B11,0) | C23: =IF(C11>0,C22/C11,0) | D23: =IF(D11>0,D22/D11,0) | E23: =IF(E11>0,E22/E11,0) | F23: =IF(F11>0,F22/F11,0)
A24: 배분 기준: 흑자 월 세전이익 합계 | B24: =SUMIFS(월별전망!$C$38:$BJ$38,월별전망!$C$6:$BJ$6,B4,월별전망!$C$38:$BJ$38,">0") | C24: =SUMIFS(월별전망!$C$38:$BJ$38,월별전망!$C$6:$BJ$6,C4,월별전망!$C$38:$BJ$38,">0") | D24: =SUMIFS(월별전망!$C$38:$BJ$38,월별전망!$C$6:$BJ$6,D4,월별전망!$C$38:$BJ$38,">0") | E24: =SUMIFS(월별전망!$C$38:$BJ$38,월별전망!$C$6:$BJ$6,E4,월별전망!$C$38:$BJ$38,">0") | F24: =SUMIFS(월별전망!$C$38:$BJ$38,월별전망!$C$6:$BJ$6,F4,월별전망!$C$38:$BJ$38,">0")
A26: 주의: 연간 세금·투자자 몫은 그 해 흑자 월에 세전이익 비율로 배분해 ‘월별전망’에 표시합니다. 적자인 해에는 0.
A27: 주의: 투자자 지분 6%는 법적으로 비용이 아니라 이익 배분(배당)입니다. 여기서는 요청대로 창업자 몫 순이익을 보기 위해 차감합니다.
